Workbook

Sheet qPL_Fact
A1: Month_Start | B1: GL | C1: Account | D1: NetAmount
A2: 45505 | C2: Application Fees | D2: 150
A3: 45505 | C3: Bank Fees | D3: 835
A4: 45505 | C4: CASH FLOW AFTER DEBT SERVICE | D4: 68254.98
A5: 45505 | C5: Cap Rate | D5: 0.10186273
A6: 45505 | C6: Cash-on-Cash (Ann.) | D6: 0.16196056
A7: 45505 | C7: Cash-on-Cash (CFADS) | D7: 0.18040964
A8: 45505 | C8: Cash-on-Cash Return | D8: 0.08
A9: 45505 | C9: DSCR | D9: 3.0309298
A10: 45505 | C10: Delinquency | D10: 13385.17
A11: 45505 | C11: EFFECTIVE GROSS INCOME (EGI) | D11: 148103.5
A12: 45505 | C12: Effective Rental Income | D12: 145779.13
A13: 45505 | C13: Expense Ratio | D13: 0.31221929
... A826: 45992 | C826: Water | D826: 18725.1

Sheet How To Use
A1: The Groves Apartments | Model Navigation Guide
A2: 6800-6810 63rd Ave N, Brooklyn Park MN 55443 | 120 Units | Built 1967
B3: PROPERTY OVERVIEW
B4: Detail | C4: Value | D4: Notes
B5: Property Name | C5: The Groves Apartments
B6: Address | C6: 6800-6810 63rd Ave N, Brooklyn Park MN 55443
B7: Total Units | C7: 120 | D7: 60 × 1BR | 60 × 2BR
B8: Rentable SF | C8: 99,300 sq ft
B9: Year Built | C9: 1967
B10: Structures | C10: 5 residential 24-unit bldgs, 6 garage bldgs, 1 clubhouse
B11: Garages | C11: 126 stalls
B12: Purchase Price | C12: $12,000,000 | D12: 2024-08-01
B13: Total Equity | C13: $4,540,000
B14: Loan Amount | C14: $8,838,399 | D14: 5.44% | 30-yr amort
B15: Loan Balance | C15: $8,639,141 | D15: Estimated current
B17: SHEET NAVIGATION
B18: Sheet Tab | C18: Description | D18: Update Frequency
B19: How To Use | C19: This sheet — model overview and navigation guide | D19: As needed
B20: Executive Summary | C20: One-page KPI dashboard: NOI, CFADS, DSCR, CoC, occupancy | D20: Monthly
B21: Assumptions | C21: Property, loan, and unit-mix inputs — yellow editable cells | D21: As needed
B22: Full P&L | C22: 17-month monthly actuals (Aug 2024 – Dec 2025) | D22: Monthly
B23: T12_PL | C23: Trailing 12-month P&L with T12 total column | D23: Monthly
B24: Trailing Analysis | C24: Period-over-period variance: prior month / 3-mo / 12-mo | D24: Monthly
B25: Distribution_Model | C25: TIC investor distribution waterfall and payout schedule | D25: Monthly
B26: TIC Ownership | C26: Ownership percentages, equity, and return metrics by entity | D26: As needed
B27: RR Summary | C27: Rent roll statistics: occupied units, avg rent, vacancy | D27: Monthly
B28: RR Input | C28: Unit-by-unit rent roll detail — monthly snapshots | D28: Monthly
B29: Unit Improvements | C29: Renovation scope, cost, and timeline by unit | D29: As needed
... B34: Rent Comps | C34: Market rent comparables from nearby properties | D34: Quarterly
B36: HOW TO UPDATE DATA MONTHLY
A37: Step | B37: Action | C37: File | D37: Column Format
B38: 1 | C38: Export P&L from property management system | D38: data/pl_actuals.csv | E38: Month, GL, Account, Amount
B39: 2 | C39: Export end-of-month rent roll snapshot | D39: data/rent_roll.csv | E39: Month, Unit, FloorPlan, MarketRent, ActualRent, Occupied
B40: 3 | C40: Export escrow / reserve transactions | D40: data/escrow_activity.csv | E40: Month, Account, Type, Amount
B41: 4 | C41: Record any unit renovation activity | D41: data/unit_improvements.csv | E41: Unit, StartDate, EndDate, Scope, Cost
B42: 5 | C42: Update CapEx profile if systems assessed | D42: data/capex_profile.csv | E42: System, Age, Condition, EstReplCost, Priority
B43: 6 | C43: Run build: python src/build.py | D43: Regenerates all sheets | E43: output/Groves_Investor_Model.xlsx
B44: 7 | C44: Validate: python tests/test_model.py <path> | D44: Checks formulas | E44: Should report 0 issues
B46: CSV RULES
B47: Date format | C47: YYYY-MM-DD (e.g. 2025-01-01)
...

Sheet Executive Summary
A1: The Groves Apartments | Executive Summary
A2: 6800-6810 63rd Ave N, Brooklyn Park MN 55443 | 120 Units | T12 Trailing 12-Month View
A3: KPI HIGHLIGHTS
A4: Metric | B4: Value | C4: Period | D4: Target / Benchmark | F4: Notes
A5: NET OPERATING INCOME (NOI) | B5: =INDEX(T12_PL!$O:$O,MATCH("NET OPERATING INCOME (NOI)",T12_PL!$B:$B,0)) | C5: T12 | F5: Key profitability indicator
A6: CASH FLOW AFTER DEBT SERVICE | B6: =INDEX(T12_PL!$O:$O,MATCH("CASH FLOW AFTER DEBT SERVICE",T12_PL!$B:$B,0)) | C6: T12 | F6: After all debt payments
A7: NET CASH FLOW | B7: =INDEX(T12_PL!$O:$O,MATCH("NET CASH FLOW",T12_PL!$B:$B,0)) | C7: T12 | F7: After capex
A8: DSCR | B8: =INDEX(T12_PL!$O:$O,MATCH("DSCR",T12_PL!$B:$B,0)) | C8: Last Mo | D8: ≥ 1.25× | F8: Debt service coverage
A9: Cap Rate (T12) | B9: =INDEX(T12_PL!$O:$O,MATCH("Cap Rate",T12_PL!$B:$B,0)) | C9: T12 Ann. | D9: 6–8% | F9: Annualized NOI / Purchase Price
A10: Cash-on-Cash Return (NCF) | B10: =INDEX(T12_PL!$O:$O,MATCH("Cash-on-Cash (Ann.)",T12_PL!$B:$B,0)) | C10: T12 Ann. | D10: 8–12% | F10: Ann. NCF / Total Equity
A11: Expense Ratio | B11: =INDEX(T12_PL!$O:$O,MATCH("Expense Ratio",T12_PL!$B:$B,0)) | C11: Last Mo | D11: < 50% | F11: OpEx / EGI
A12: Effective Gross Income | B12: =INDEX(T12_PL!$O:$O,MATCH("EFFECTIVE GROSS INCOME (EGI)",T12_PL!$B:$B,0)) | C12: T12
A13: Total Operating Expenses | B13: =INDEX(T12_PL!$O:$O,MATCH("Total Operating Expenses",T12_PL!$B:$B,0)) | C13: T12
A15: T12 INCOME SUMMARY
A16: Line Item | B16: T12 Total
A17: Gross Potential Rent | B17: =INDEX(T12_PL!$O:$O,MATCH("Gross Potential Rent",T12_PL!$B:$B,0))
A18: Loss/Gain to Market | B18: =INDEX(T12_PL!$O:$O,MATCH("Loss/Gain to Market",T12_PL!$B:$B,0))
A19: Vacancy | B19: =INDEX(T12_PL!$O:$O,MATCH("Vacancy",T12_PL!$B:$B,0))
A20: Delinquency | B20: =INDEX(T12_PL!$O:$O,MATCH("Delinquency",T12_PL!$B:$B,0))
A21: Effective Rental Income | B21: =INDEX(T12_PL!$O:$O,MATCH("Effective Rental Income",T12_PL!$B:$B,0))
A22: Total Other Income | B22: =INDEX(T12_PL!$O:$O,MATCH("Total Other Income",T12_PL!$B:$B,0))
A23: EFFECTIVE GROSS INCOME (EGI) | B23: =INDEX(T12_PL!$O:$O,MATCH("EFFECTIVE GROSS INCOME (EGI)",T12_PL!$B:$B,0))
A24: Total Operating Expenses | B24: =INDEX(T12_PL!$O:$O,MATCH("Total Operating Expenses",T12_PL!$B:$B,0))
A25: NET OPERATING INCOME (NOI) | B25: =INDEX(T12_PL!$O:$O,MATCH("NET OPERATING INCOME (NOI)",T12_PL!$B:$B,0))
A26: Total Debt Service | B26: =INDEX(T12_PL!$O:$O,MATCH("Total Debt Service",T12_PL!$B:$B,0))
A27: CASH FLOW AFTER DEBT SERVICE | B27: =INDEX(T12_PL!$O:$O,MATCH("CASH FLOW AFTER DEBT SERVICE",T12_PL!$B:$B,0))
A29: PROPERTY DETAILS
A30: Property | B30: The Groves Apartments
A31: Address | B31: 6800-6810 63rd Ave N, Brooklyn Park MN 55443
A32: Units | B32: 120
A33: Purchase Price | B33: $12,000,000
A34: Purchase Date | B34: 2024-08-01
A36: DEBT SUMMARY
A37: Original Loan | B37: $8,838,399
A38: Rate | B38: 5.44% | 30-yr amort
A39: Est. Balance | B39: $8,639,141
A40: Term | B40: 5-yr term | Matures ~2029
A42: INVESTOR RETURNS
A43: Entity | B43: Ownership % | C43: Equity
A44: Boxwood LLC | B44: 61.674% | F44: $2,800,000
...

Sheet Assumptions
A1: The Groves Apartments | Model Assumptions
A2: Edit yellow cells to update property, loan, and unit-mix inputs.
A3: PROPERTY
A4: Input | B4: Value | C4: Notes
A5: Property Name | B5: The Groves Apartments
A6: Address | B6: 6800-6810 63rd Ave N, Brooklyn Park MN 55443
A7: Total Units | B7: 120 | C7: Residential units
A8: Rentable SF | B8: 99300
A9: Year Built | B9: 1967
A10: Purchase Price | B10: 12000000
A11: Purchase Date | B11: 2024-08-01
A12: Total Equity | B12: 4540000
A13: Structures | B13: 5 residential 24-unit bldgs, 6 garage bldgs, 1 clubhouse
A14: Garage Stalls | B14: 126
A16: UNIT MIX
A17: Type | B17: Count | C17: SF | D17: Market Rent | E17: Baths
A18: 1BR | B18: 60 | C18: 765 | D18: 1350 | E18: 1
A19: 2BR | B19: 60 | C19: 890 | D19: 1550 | E19: 1
A21: LOAN
A22: Input | B22: Value | C22: Notes
A23: Original Amount | B23: 8838399
A24: Interest Rate | B24: 0.0544
A25: Amortization | B25: 30 | C25: Years
A26: Loan Term | B26: 5 | C26: Years
A27: Start Date | B27: 2024-08-01
A28: Est. Current Balance | B28: 8639141
A29: Interest Only | B29: No | C29: I/O period
A31: TIC OWNERSHIP
A32: Entity | B32: Ownership % | C32: Equity Invested
A33: Boxwood LLC | B33: 0.61674 | C33: 2799999.6
A34: Groves LP LLC | B34: 0.31718 | C34: 1439997.2
A35: E 2088 | B35: 0.06608 | C35: 300003.2
A37: VALUATION
A38: Scenario | B38: Value | C38: Notes
A39: BOV Low | B39: 14700000
A40: BOV Mid | B40: 15000000 | C40: Used in TIC Ownership Est. Value
A41: BOV High | B41: 15300000
A43: REFINANCE ASSUMPTIONS
A44: Input | B44: Value | C44: Notes
A45: Projected Value | B45: 15000000
...

Sheet Full P&L
A1: The Groves Apartments | Full P&L — Monthly Actuals
A2: 6800-6810 63rd Ave N, Brooklyn Park MN 55443 | 17 Months
A3: GL | B3: Account | C3: T12 TTM | D3: 45505 | E3: 45536 | F3: 45566 | G3: 45597 | H3: 45627 | I3: 45658 | J3: 45689 | K3: 45717 | L3: 45748 | M3: 45778 | N3: 45809 | O3: 45839 | P3: 45870 | Q3: 45901 | R3: 45931 | S3: 45962 | T3: 45992
B4: REVENUE | C4: =SUM(I4:T4) | D4: =SUMIFS(qPL_Fact!$D:$D,qPL_Fact!$C:$C,$B4,qPL_Fact!$A:$A,D$3) | E4: =SUMIFS(qPL_Fact!$D:$D,qPL_Fact!$C:$C,$B4,qPL_Fact!$A:$A,E$3) | F4: =SUMIFS(qPL_Fact!$D:$D,qPL_Fact!$C:$C,$B4,qPL_Fact!$A:$A,F$3) | G4: =SUMIFS(qPL_Fact!$D:$D,qPL_Fact!$C:$C,$B4,qPL_Fact!$A:$A,G$3) | H4: =SUMIFS(qPL_Fact!$D:$D,qPL_Fact!$C:$C,$B4,qPL_Fact!$A:$A,H$3) | I4: =SUMIFS(qPL_Fact!$D:$D,qPL_Fact!$C:$C,$B4,qPL_Fact!$A:$A,I$3) | J4: =SUMIFS(qPL_Fact!$D:$D,qPL_Fact!$C:$C,$B4,qPL_Fact!$A:$A,J$3) | K4: =SUMIFS(qPL_Fact!$D:$D,qPL_Fact!$C:$C,$B4,qPL_Fact!$A:$A,K$3) | ... T4: =SUMIFS(qPL_Fact!$D:$D,qPL_Fact!$C:$C,$B4,qPL_Fact!$A:$A,T$3)
A5: 3090 | B5: Gross Potential Rent | C5: =SUM(I5:T5) | D5: =SUMIFS(qPL_Fact!$D:$D,qPL_Fact!$C:$C,$B5,qPL_Fact!$A:$A,D$3) | E5: =SUMIFS(qPL_Fact!$D:$D,qPL_Fact!$C:$C,$B5,qPL_Fact!$A:$A,E$3) | F5: =SUMIFS(qPL_Fact!$D:$D,qPL_Fact!$C:$C,$B5,qPL_Fact!$A:$A,F$3) | G5: =SUMIFS(qPL_Fact!$D:$D,qPL_Fact!$C:$C,$B5,qPL_Fact!$A:$A,G$3) | H5: =SUMIFS(qPL_Fact!$D:$D,qPL_Fact!$C:$C,$B5,qPL_Fact!$A:$A,H$3) | I5: =SUMIFS(qPL_Fact!$D:$D,qPL_Fact!$C:$C,$B5,qPL_Fact!$A:$A,I$3) | J5: =SUMIFS(qPL_Fact!$D:$D,qPL_Fact!$C:$C,$B5,qPL_Fact!$A:$A,J$3) | K5: =SUMIFS(qPL_Fact!$D:$D,qPL_Fact!$C:$C,$B5,qPL_Fact!$A:$A,K$3) | ... T5: =SUMIFS(qPL_Fact!$D:$D,qPL_Fact!$C:$C,$B5,qPL_Fact!$A:$A,T$3)
A6: 4100 | B6: Loss/Gain to Market | C6: =SUM(I6:T6) | D6: =SUMIFS(qPL_Fact!$D:$D,qPL_Fact!$C:$C,$B6,qPL_Fact!$A:$A,D$3) | E6: =SUMIFS(qPL_Fact!$D:$D,qPL_Fact!$C:$C,$B6,qPL_Fact!$A:$A,E$3) | F6: =SUMIFS(qPL_Fact!$D:$D,qPL_Fact!$C:$C,$B6,qPL_Fact!$A:$A,F$3) | G6: =SUMIFS(qPL_Fact!$D:$D,qPL_Fact!$C:$C,$B6,qPL_Fact!$A:$A,G$3) | H6: =SUMIFS(qPL_Fact!$D:$D,qPL_Fact!$C:$C,$B6,qPL_Fact!$A:$A,H$3) | I6: =SUMIFS(qPL_Fact!$D:$D,qPL_Fact!$C:$C,$B6,qPL_Fact!$A:$A,I$3) | J6: =SUMIFS(qPL_Fact!$D:$D,qPL_Fact!$C:$C,$B6,qPL_Fact!$A:$A,J$3) | K6: =SUMIFS(qPL_Fact!$D:$D,qPL_Fact!$C:$C,$B6,qPL_Fact!$A:$A,K$3) | ... T6: =SUMIFS(qPL_Fact!$D:$D,qPL_Fact!$C:$C,$B6,qPL_Fact!$A:$A,T$3)
A7: 4100 | B7: Delinquency | C7: =SUM(I7:T7) | D7: =SUMIFS(qPL_Fact!$D:$D,qPL_Fact!$C:$C,$B7,qPL_Fact!$A:$A,D$3) | E7: =SUMIFS(qPL_Fact!$D:$D,qPL_Fact!$C:$C,$B7,qPL_Fact!$A:$A,E$3) | F7: =SUMIFS(qPL_Fact!$D:$D,qPL_Fact!$C:$C,$B7,qPL_Fact!$A:$A,F$3) | G7: =SUMIFS(qPL_Fact!$D:$D,qPL_Fact!$C:$C,$B7,qPL_Fact!$A:$A,G$3) | H7: =SUMIFS(qPL_Fact!$D:$D,qPL_Fact!$C:$C,$B7,qPL_Fact!$A:$A,H$3) | I7: =SUMIFS(qPL_Fact!$D:$D,qPL_Fact!$C:$C,$B7,qPL_Fact!$A:$A,I$3) | J7: =SUMIFS(qPL_Fact!$D:$D,qPL_Fact!$C:$C,$B7,qPL_Fact!$A:$A,J$3) | K7: =SUMIFS(qPL_Fact!$D:$D,qPL_Fact!$C:$C,$B7,qPL_Fact!$A:$A,K$3) | ... T7: =SUMIFS(qPL_Fact!$D:$D,qPL_Fact!$C:$C,$B7,qPL_Fact!$A:$A,T$3)
A8: 4100 | B8: Vacancy | C8: =SUM(I8:T8) | D8: =SUMIFS(qPL_Fact!$D:$D,qPL_Fact!$C:$C,$B8,qPL_Fact!$A:$A,D$3) | E8: =SUMIFS(qPL_Fact!$D:$D,qPL_Fact!$C:$C,$B8,qPL_Fact!$A:$A,E$3) | F8: =SUMIFS(qPL_Fact!$D:$D,qPL_Fact!$C:$C,$B8,qPL_Fact!$A:$A,F$3) | G8: =SUMIFS(qPL_Fact!$D:$D,qPL_Fact!$C:$C,$B8,qPL_Fact!$A:$A,G$3) | H8: =SUMIFS(qPL_Fact!$D:$D,qPL_Fact!$C:$C,$B8,qPL_Fact!$A:$A,H$3) | I8: =SUMIFS(qPL_Fact!$D:$D,qPL_Fact!$C:$C,$B8,qPL_Fact!$A:$A,I$3) | J8: =SUMIFS(qPL_Fact!$D:$D,qPL_Fact!$C:$C,$B8,qPL_Fact!$A:$A,J$3) | K8: =SUMIFS(qPL_Fact!$D:$D,qPL_Fact!$C:$C,$B8,qPL_Fact!$A:$A,K$3) | ... T8: =SUMIFS(qPL_Fact!$D:$D,qPL_Fact!$C:$C,$B8,qPL_Fact!$A:$A,T$3)
B9: Concessions | C9: =SUM(I9:T9) | D9: =SUMIFS(qPL_Fact!$D:$D,qPL_Fact!$C:$C,$B9,qPL_Fact!$A:$A,D$3) | E9: =SUMIFS(qPL_Fact!$D:$D,qPL_Fact!$C:$C,$B9,qPL_Fact!$A:$A,E$3) | F9: =SUMIFS(qPL_Fact!$D:$D,qPL_Fact!$C:$C,$B9,qPL_Fact!$A:$A,F$3) | G9: =SUMIFS(qPL_Fact!$D:$D,qPL_Fact!$C:$C,$B9,qPL_Fact!$A:$A,G$3) | H9: =SUMIFS(qPL_Fact!$D:$D,qPL_Fact!$C:$C,$B9,qPL_Fact!$A:$A,H$3) | I9: =SUMIFS(qPL_Fact!$D:$D,qPL_Fact!$C:$C,$B9,qPL_Fact!$A:$A,I$3) | J9: =SUMIFS(qPL_Fact!$D:$D,qPL_Fact!$C:$C,$B9,qPL_Fact!$A:$A,J$3) | K9: =SUMIFS(qPL_Fact!$D:$D,qPL_Fact!$C:$C,$B9,qPL_Fact!$A:$A,K$3) | ... T9: =SUMIFS(qPL_Fact!$D:$D,qPL_Fact!$C:$C,$B9,qPL_Fact!$A:$A,T$3)
A10: 4700 | B10: Other Rent Adjustments | C10: =SUM(I10:T10) | D10: =SUMIFS(qPL_Fact!$D:$D,qPL_Fact!$C:$C,$B10,qPL_Fact!$A:$A,D$3) | E10: =SUMIFS(qPL_Fact!$D:$D,qPL_Fact!$C:$C,$B10,qPL_Fact!$A:$A,E$3) | F10: =SUMIFS(qPL_Fact!$D:$D,qPL_Fact!$C:$C,$B10,qPL_Fact!$A:$A,F$3) | G10: =SUMIFS(qPL_Fact!$D:$D,qPL_Fact!$C:$C,$B10,qPL_Fact!$A:$A,G$3) | H10: =SUMIFS(qPL_Fact!$D:$D,qPL_Fact!$C:$C,$B10,qPL_Fact!$A:$A,H$3) | I10: =SUMIFS(qPL_Fact!$D:$D,qPL_Fact!$C:$C,$B10,qPL_Fact!$A:$A,I$3) | J10: =SUMIFS(qPL_Fact!$D:$D,qPL_Fact!$C:$C,$B10,qPL_Fact!$A:$A,J$3) | K10: =SUMIFS(qPL_Fact!$D:$D,qPL_Fact!$C:$C,$B10,qPL_Fact!$A:$A,K$3) | ... T10: =SUMIFS(qPL_Fact!$D:$D,qPL_Fact!$C:$C,$B10,qPL_Fact!$A:$A,T$3)
B11: Effective Rental Income | C11: =SUM(I11:T11) | D11: =SUMIFS(qPL_Fact!$D:$D,qPL_Fact!$C:$C,$B11,qPL_Fact!$A:$A,D$3) | E11: =SUMIFS(qPL_Fact!$D:$D,qPL_Fact!$C:$C,$B11,qPL_Fact!$A:$A,E$3) | F11: =SUMIFS(qPL_Fact!$D:$D,qPL_Fact!$C:$C,$B11,qPL_Fact!$A:$A,F$3) | G11: =SUMIFS(qPL_Fact!$D:$D,qPL_Fact!$C:$C,$B11,qPL_Fact!$A:$A,G$3) | H11: =SUMIFS(qPL_Fact!$D:$D,qPL_Fact!$C:$C,$B11,qPL_Fact!$A:$A,H$3) | I11: =SUMIFS(qPL_Fact!$D:$D,qPL_Fact!$C:$C,$B11,qPL_Fact!$A:$A,I$3) | J11: =SUMIFS(qPL_Fact!$D:$D,qPL_Fact!$C:$C,$B11,qPL_Fact!$A:$A,J$3) | K11: =SUMIFS(qPL_Fact!$D:$D,qPL_Fact!$C:$C,$B11,qPL_Fact!$A:$A,K$3) | ... T11: =SUMIFS(qPL_Fact!$D:$D,qPL_Fact!$C:$C,$B11,qPL_Fact!$A:$A,T$3)
B13: OTHER INCOME | C13: =SUM(I13:T13) | D13: =SUMIFS(qPL_Fact!$D:$D,qPL_Fact!$C:$C,$B13,qPL_Fact!$A:$A,D$3) | E13: =SUMIFS(qPL_Fact!$D:$D,qPL_Fact!$C:$C,$B13,qPL_Fact!$A:$A,E$3) | F13: =SUMIFS(qPL_Fact!$D:$D,qPL_Fact!$C:$C,$B13,qPL_Fact!$A:$A,F$3) | G13: =SUMIFS(qPL_Fact!$D:$D,qPL_Fact!$C:$C,$B13,qPL_Fact!$A:$A,G$3) | H13: =SUMIFS(qPL_Fact!$D:$D,qPL_Fact!$C:$C,$B13,qPL_Fact!$A:$A,H$3) | I13: =SUMIFS(qPL_Fact!$D:$D,qPL_Fact!$C:$C,$B13,qPL_Fact!$A:$A,I$3) | J13: =SUMIFS(qPL_Fact!$D:$D,qPL_Fact!$C:$C,$B13,qPL_Fact!$A:$A,J$3) | K13: =SUMIFS(qPL_Fact!$D:$D,qPL_Fact!$C:$C,$B13,qPL_Fact!$A:$A,K$3) | ... T13: =SUMIFS(qPL_Fact!$D:$D,qPL_Fact!$C:$C,$B13,qPL_Fact!$A:$A,T$3)
A14: 4460 | B14: Late Fees | C14: =SUM(I14:T14) | D14: =SUMIFS(qPL_Fact!$D:$D,qPL_Fact!$C:$C,$B14,qPL_Fact!$A:$A,D$3) | E14: =SUMIFS(qPL_Fact!$D:$D,qPL_Fact!$C:$C,$B14,qPL_Fact!$A:$A,E$3) | F14: =SUMIFS(qPL_Fact!$D:$D,qPL_Fact!$C:$C,$B14,qPL_Fact!$A:$A,F$3) | G14: =SUMIFS(qPL_Fact!$D:$D,qPL_Fact!$C:$C,$B14,qPL_Fact!$A:$A,G$3) | H14: =SUMIFS(qPL_Fact!$D:$D,qPL_Fact!$C:$C,$B14,qPL_Fact!$A:$A,H$3) | I14: =SUMIFS(qPL_Fact!$D:$D,qPL_Fact!$C:$C,$B14,qPL_Fact!$A:$A,I$3) | J14: =SUMIFS(qPL_Fact!$D:$D,qPL_Fact!$C:$C,$B14,qPL_Fact!$A:$A,J$3) | K14: =SUMIFS(qPL_Fact!$D:$D,qPL_Fact!$C:$C,$B14,qPL_Fact!$A:$A,K$3) | ... T14: =SUMIFS(qPL_Fact!$D:$D,qPL_Fact!$C:$C,$B14,qPL_Fact!$A:$A,T$3)
A15: 4490 | B15: Move-In Fees | C15: =SUM(I15:T15) | D15: =SUMIFS(qPL_Fact!$D:$D,qPL_Fact!$C:$C,$B15,qPL_Fact!$A:$A,D$3) | E15: =SUMIFS(qPL_Fact!$D:$D,qPL_Fact!$C:$C,$B15,qPL_Fact!$A:$A,E$3) | F15: =SUMIFS(qPL_Fact!$D:$D,qPL_Fact!$C:$C,$B15,qPL_Fact!$A:$A,F$3) | G15: =SUMIFS(qPL_Fact!$D:$D,qPL_Fact!$C:$C,$B15,qPL_Fact!$A:$A,G$3) | H15: =SUMIFS(qPL_Fact!$D:$D,qPL_Fact!$C:$C,$B15,qPL_Fact!$A:$A,H$3) | I15: =SUMIFS(qPL_Fact!$D:$D,qPL_Fact!$C:$C,$B15,qPL_Fact!$A:$A,I$3) | J15: =SUMIFS(qPL_Fact!$D:$D,qPL_Fact!$C:$C,$B15,qPL_Fact!$A:$A,J$3) | K15: =SUMIFS(qPL_Fact!$D:$D,qPL_Fact!$C:$C,$B15,qPL_Fact!$A:$A,K$3) | ... T15: =SUMIFS(qPL_Fact!$D:$D,qPL_Fact!$C:$C,$B15,qPL_Fact!$A:$A,T$3)
A16: 4440 | B16: Application Fees | C16: =SUM(I16:T16) | D16: =SUMIFS(qPL_Fact!$D:$D,qPL_Fact!$C:$C,$B16,qPL_Fact!$A:$A,D$3) | E16: =SUMIFS(qPL_Fact!$D:$D,qPL_Fact!$C:$C,$B16,qPL_Fact!$A:$A,E$3) | F16: =SUMIFS(qPL_Fact!$D:$D,qPL_Fact!$C:$C,$B16,qPL_Fact!$A:$A,F$3) | G16: =SUMIFS(qPL_Fact!$D:$D,qPL_Fact!$C:$C,$B16,qPL_Fact!$A:$A,G$3) | H16: =SUMIFS(qPL_Fact!$D:$D,qPL_Fact!$C:$C,$B16,qPL_Fact!$A:$A,H$3) | I16: =SUMIFS(qPL_Fact!$D:$D,qPL_Fact!$C:$C,$B16,qPL_Fact!$A:$A,I$3) | J16: =SUMIFS(qPL_Fact!$D:$D,qPL_Fact!$C:$C,$B16,qPL_Fact!$A:$A,J$3) | K16: =SUMIFS(qPL_Fact!$D:$D,qPL_Fact!$C:$C,$B16,qPL_Fact!$A:$A,K$3) | ... T16: =SUMIFS(qPL_Fact!$D:$D,qPL_Fact!$C:$C,$B16,qPL_Fact!$A:$A,T$3)
A17: 4415 | B17: Internet Charges | C17: =SUM(I17:T17) | D17: =SUMIFS(qPL_Fact!$D:$D,qPL_Fact!$C:$C,$B17,qPL_Fact!$A:$A,D$3) | E17: =SUMIFS(qPL_Fact!$D:$D,qPL_Fact!$C:$C,$B17,qPL_Fact!$A:$A,E$3) | F17: =SUMIFS(qPL_Fact!$D:$D,qPL_Fact!$C:$C,$B17,qPL_Fact!$A:$A,F$3) | G17: =SUMIFS(qPL_Fact!$D:$D,qPL_Fact!$C:$C,$B17,qPL_Fact!$A:$A,G$3) | H17: =SUMIFS(qPL_Fact!$D:$D,qPL_Fact!$C:$C,$B17,qPL_Fact!$A:$A,H$3) | I17: =SUMIFS(qPL_Fact!$D:$D,qPL_Fact!$C:$C,$B17,qPL_Fact!$A:$A,I$3) | J17: =SUMIFS(qPL_Fact!$D:$D,qPL_Fact!$C:$C,$B17,qPL_Fact!$A:$A,J$3) | K17: =SUMIFS(qPL_Fact!$D:$D,qPL_Fact!$C:$C,$B17,qPL_Fact!$A:$A,K$3) | ... T17: =SUMIFS(qPL_Fact!$D:$D,qPL_Fact!$C:$C,$B17,qPL_Fact!$A:$A,T$3)
A18: 4450 | B18: Insurance Services | C18: =SUM(I18:T18) | D18: =SUMIFS(qPL_Fact!$D:$D,qPL_Fact!$C:$C,$B18,qPL_Fact!$A:$A,D$3) | E18: =SUMIFS(qPL_Fact!$D:$D,qPL_Fact!$C:$C,$B18,qPL_Fact!$A:$A,E$3) | F18: =SUMIFS(qPL_Fact!$D:$D,qPL_Fact!$C:$C,$B18,qPL_Fact!$A:$A,F$3) | G18: =SUMIFS(qPL_Fact!$D:$D,qPL_Fact!$C:$C,$B18,qPL_Fact!$A:$A,G$3) | H18: =SUMIFS(qPL_Fact!$D:$D,qPL_Fact!$C:$C,$B18,qPL_Fact!$A:$A,H$3) | I18: =SUMIFS(qPL_Fact!$D:$D,qPL_Fact!$C:$C,$B18,qPL_Fact!$A:$A,I$3) | J18: =SUMIFS(qPL_Fact!$D:$D,qPL_Fact!$C:$C,$B18,qPL_Fact!$A:$A,J$3) | K18: =SUMIFS(qPL_Fact!$D:$D,qPL_Fact!$C:$C,$B18,qPL_Fact!$A:$A,K$3) | ... T18: =SUMIFS(qPL_Fact!$D:$D,qPL_Fact!$C:$C,$B18,qPL_Fact!$A:$A,T$3)
B19: Interest Income | C19: =SUM(I19:T19) | D19: =SUMIFS(qPL_Fact!$D:$D,qPL_Fact!$C:$C,$B19,qPL_Fact!$A:$A,D$3) | E19: =SUMIFS(qPL_Fact!$D:$D,qPL_Fact!$C:$C,$B19,qPL_Fact!$A:$A,E$3) | F19: =SUMIFS(qPL_Fact!$D:$D,qPL_Fact!$C:$C,$B19,qPL_Fact!$A:$A,F$3) | G19: =SUMIFS(qPL_Fact!$D:$D,qPL_Fact!$C:$C,$B19,qPL_Fact!$A:$A,G$3) | H19: =SUMIFS(qPL_Fact!$D:$D,qPL_Fact!$C:$C,$B19,qPL_Fact!$A:$A,H$3) | I19: =SUMIFS(qPL_Fact!$D:$D,qPL_Fact!$C:$C,$B19,qPL_Fact!$A:$A,I$3) | J19: =SUMIFS(qPL_Fact!$D:$D,qPL_Fact!$C:$C,$B19,qPL_Fact!$A:$A,J$3) | K19: =SUMIFS(qPL_Fact!$D:$D,qPL_Fact!$C:$C,$B19,qPL_Fact!$A:$A,K$3) | ... T19: =SUMIFS(qPL_Fact!$D:$D,qPL_Fact!$C:$C,$B19,qPL_Fact!$A:$A,T$3)
A20: 4730 | B20: Utility Reimbursement | C20: =SUM(I20:T20) | D20: =SUMIFS(qPL_Fact!$D:$D,qPL_Fact!$C:$C,$B20,qPL_Fact!$A:$A,D$3) | E20: =SUMIFS(qPL_Fact!$D:$D,qPL_Fact!$C:$C,$B20,qPL_Fact!$A:$A,E$3) | F20: =SUMIFS(qPL_Fact!$D:$D,qPL_Fact!$C:$C,$B20,qPL_Fact!$A:$A,F$3) | G20: =SUMIFS(qPL_Fact!$D:$D,qPL_Fact!$C:$C,$B20,qPL_Fact!$A:$A,G$3) | H20: =SUMIFS(qPL_Fact!$D:$D,qPL_Fact!$C:$C,$B20,qPL_Fact!$A:$A,H$3) | I20: =SUMIFS(qPL_Fact!$D:$D,qPL_Fact!$C:$C,$B20,qPL_Fact!$A:$A,I$3) | J20: =SUMIFS(qPL_Fact!$D:$D,qPL_Fact!$C:$C,$B20,qPL_Fact!$A:$A,J$3) | K20: =SUMIFS(qPL_Fact!$D:$D,qPL_Fact!$C:$C,$B20,qPL_Fact!$A:$A,K$3) | ... T20: =SUMIFS(qPL_Fact!$D:$D,qPL_Fact!$C:$C,$B20,qPL_Fact!$A:$A,T$3)
B21: Deposit Forfeit | C21: =SUM(I21:T21) | D21: =SUMIFS(qPL_Fact!$D:$D,qPL_Fact!$C:$C,$B21,qPL_Fact!$A:$A,D$3) | E21: =SUMIFS(qPL_Fact!$D:$D,qPL_Fact!$C:$C,$B21,qPL_Fact!$A:$A,E$3) | F21: =SUMIFS(qPL_Fact!$D:$D,qPL_Fact!$C:$C,$B21,qPL_Fact!$A:$A,F$3) | G21: =SUMIFS(qPL_Fact!$D:$D,qPL_Fact!$C:$C,$B21,qPL_Fact!$A:$A,G$3) | H21: =SUMIFS(qPL_Fact!$D:$D,qPL_Fact!$C:$C,$B21,qPL_Fact!$A:$A,H$3) | I21: =SUMIFS(qPL_Fact!$D:$D,qPL_Fact!$C:$C,$B21,qPL_Fact!$A:$A,I$3) | J21: =SUMIFS(qPL_Fact!$D:$D,qPL_Fact!$C:$C,$B21,qPL_Fact!$A:$A,J$3) | K21: =SUMIFS(qPL_Fact!$D:$D,qPL_Fact!$C:$C,$B21,qPL_Fact!$A:$A,K$3) | ... T21: =SUMIFS(qPL_Fact!$D:$D,qPL_Fact!$C:$C,$B21,qPL_Fact!$A:$A,T$3)
A22: 4410 | B22: NSF Fees | C22: =SUM(I22:T22) | D22: =SUMIFS(qPL_Fact!$D:$D,qPL_Fact!$C:$C,$B22,qPL_Fact!$A:$A,D$3) | E22: =SUMIFS(qPL_Fact!$D:$D,qPL_Fact!$C:$C,$B22,qPL_Fact!$A:$A,E$3) | F22: =SUMIFS(qPL_Fact!$D:$D,qPL_Fact!$C:$C,$B22,qPL_Fact!$A:$A,F$3) | G22: =SUMIFS(qPL_Fact!$D:$D,qPL_Fact!$C:$C,$B22,qPL_Fact!$A:$A,G$3) | H22: =SUMIFS(qPL_Fact!$D:$D,qPL_Fact!$C:$C,$B22,qPL_Fact!$A:$A,H$3) | I22: =SUMIFS(qPL_Fact!$D:$D,qPL_Fact!$C:$C,$B22,qPL_Fact!$A:$A,I$3) | J22: =SUMIFS(qPL_Fact!$D:$D,qPL_Fact!$C:$C,$B22,qPL_Fact!$A:$A,J$3) | K22: =SUMIFS(qPL_Fact!$D:$D,qPL_Fact!$C:$C,$B22,qPL_Fact!$A:$A,K$3) | ... T22: =SUMIFS(qPL_Fact!$D:$D,qPL_Fact!$C:$C,$B22,qPL_Fact!$A:$A,T$3)
B23: Total Other Income | C23: =SUM(I23:T23) | D23: =SUMIFS(qPL_Fact!$D:$D,qPL_Fact!$C:$C,$B23,qPL_Fact!$A:$A,D$3) | E23: =SUMIFS(qPL_Fact!$D:$D,qPL_Fact!$C:$C,$B23,qPL_Fact!$A:$A,E$3) | F23: =SUMIFS(qPL_Fact!$D:$D,qPL_Fact!$C:$C,$B23,qPL_Fact!$A:$A,F$3) | G23: =SUMIFS(qPL_Fact!$D:$D,qPL_Fact!$C:$C,$B23,qPL_Fact!$A:$A,G$3) | H23: =SUMIFS(qPL_Fact!$D:$D,qPL_Fact!$C:$C,$B23,qPL_Fact!$A:$A,H$3) | I23: =SUMIFS(qPL_Fact!$D:$D,qPL_Fact!$C:$C,$B23,qPL_Fact!$A:$A,I$3) | J23: =SUMIFS(qPL_Fact!$D:$D,qPL_Fact!$C:$C,$B23,qPL_Fact!$A:$A,J$3) | K23: =SUMIFS(qPL_Fact!$D:$D,qPL_Fact!$C:$C,$B23,qPL_Fact!$A:$A,K$3) | ... T23: =SUMIFS(qPL_Fact!$D:$D,qPL_Fact!$C:$C,$B23,qPL_Fact!$A:$A,T$3)
B25: EFFECTIVE GROSS INCOME (EGI) | C25: =SUM(I25:T25) | D25: =SUMIFS(qPL_Fact!$D:$D,qPL_Fact!$C:$C,$B25,qPL_Fact!$A:$A,D$3) | E25: =SUMIFS(qPL_Fact!$D:$D,qPL_Fact!$C:$C,$B25,qPL_Fact!$A:$A,E$3) | F25: =SUMIFS(qPL_Fact!$D:$D,qPL_Fact!$C:$C,$B25,qPL_Fact!$A:$A,F$3) | G25: =SUMIFS(qPL_Fact!$D:$D,qPL_Fact!$C:$C,$B25,qPL_Fact!$A:$A,G$3) | H25: =SUMIFS(qPL_Fact!$D:$D,qPL_Fact!$C:$C,$B25,qPL_Fact!$A:$A,H$3) | I25: =SUMIFS(qPL_Fact!$D:$D,qPL_Fact!$C:$C,$B25,qPL_Fact!$A:$A,I$3) | J25: =SUMIFS(qPL_Fact!$D:$D,qPL_Fact!$C:$C,$B25,qPL_Fact!$A:$A,J$3) | K25: =SUMIFS(qPL_Fact!$D:$D,qPL_Fact!$C:$C,$B25,qPL_Fact!$A:$A,K$3) | ... T25: =SUMIFS(qPL_Fact!$D:$D,qPL_Fact!$C:$C,$B25,qPL_Fact!$A:$A,T$3)
B27: OPERATING EXPENSES | C27: =SUM(I27:T27) | D27: =SUMIFS(qPL_Fact!$D:$D,qPL_Fact!$C:$C,$B27,qPL_Fact!$A:$A,D$3) | E27: =SUMIFS(qPL_Fact!$D:$D,qPL_Fact!$C:$C,$B27,qPL_Fact!$A:$A,E$3) | F27: =SUMIFS(qPL_Fact!$D:$D,qPL_Fact!$C:$C,$B27,qPL_Fact!$A:$A,F$3) | G27: =SUMIFS(qPL_Fact!$D:$D,qPL_Fact!$C:$C,$B27,qPL_Fact!$A:$A,G$3) | H27: =SUMIFS(qPL_Fact!$D:$D,qPL_Fact!$C:$C,$B27,qPL_Fact!$A:$A,H$3) | I27: =SUMIFS(qPL_Fact!$D:$D,qPL_Fact!$C:$C,$B27,qPL_Fact!$A:$A,I$3) | J27: =SUMIFS(qPL_Fact!$D:$D,qPL_Fact!$C:$C,$B27,qPL_Fact!$A:$A,J$3) | K27: =SUMIFS(qPL_Fact!$D:$D,qPL_Fact!$C:$C,$B27,qPL_Fact!$A:$A,K$3) | ... T27: =SUMIFS(qPL_Fact!$D:$D,qPL_Fact!$C:$C,$B27,qPL_Fact!$A:$A,T$3)
A28: 6161 | B28: Real Estate Taxes | C28: =SUM(I28:T28) | D28: =SUMIFS(qPL_Fact!$D:$D,qPL_Fact!$C:$C,$B28,qPL_Fact!$A:$A,D$3) | E28: =SUMIFS(qPL_Fact!$D:$D,qPL_Fact!$C:$C,$B28,qPL_Fact!$A:$A,E$3) | F28: =SUMIFS(qPL_Fact!$D:$D,qPL_Fact!$C:$C,$B28,qPL_Fact!$A:$A,F$3) | G28: =SUMIFS(qPL_Fact!$D:$D,qPL_Fact!$C:$C,$B28,qPL_Fact!$A:$A,G$3) | H28: =SUMIFS(qPL_Fact!$D:$D,qPL_Fact!$C:$C,$B28,qPL_Fact!$A:$A,H$3) | I28: =SUMIFS(qPL_Fact!$D:$D,qPL_Fact!$C:$C,$B28,qPL_Fact!$A:$A,I$3) | J28: =SUMIFS(qPL_Fact!$D:$D,qPL_Fact!$C:$C,$B28,qPL_Fact!$A:$A,J$3) | K28: =SUMIFS(qPL_Fact!$D:$D,qPL_Fact!$C:$C,$B28,qPL_Fact!$A:$A,K$3) | ... T28: =SUMIFS(qPL_Fact!$D:$D,qPL_Fact!$C:$C,$B28,qPL_Fact!$A:$A,T$3)
A29: 6091 | B29: Property Insurance | C29: =SUM(I29:T29) | D29: =SUMIFS(qPL_Fact!$D:$D,qPL_Fact!$C:$C,$B29,qPL_Fact!$A:$A,D$3) | E29: =SUMIFS(qPL_Fact!$D:$D,qPL_Fact!$C:$C,$B29,qPL_Fact!$A:$A,E$3) | F29: =SUMIFS(qPL_Fact!$D:$D,qPL_Fact!$C:$C,$B29,qPL_Fact!$A:$A,F$3) | G29: =SUMIFS(qPL_Fact!$D:$D,qPL_Fact!$C:$C,$B29,qPL_Fact!$A:$A,G$3) | H29: =SUMIFS(qPL_Fact!$D:$D,qPL_Fact!$C:$C,$B29,qPL_Fact!$A:$A,H$3) | I29: =SUMIFS(qPL_Fact!$D:$D,qPL_Fact!$C:$C,$B29,qPL_Fact!$A:$A,I$3) | J29: =SUMIFS(qPL_Fact!$D:$D,qPL_Fact!$C:$C,$B29,qPL_Fact!$A:$A,J$3) | K29: =SUMIFS(qPL_Fact!$D:$D,qPL_Fact!$C:$C,$B29,qPL_Fact!$A:$A,K$3) | ... T29: =SUMIFS(qPL_Fact!$D:$D,qPL_Fact!$C:$C,$B29,qPL_Fact!$A:$A,T$3)
A30: 6002 | B30: Payroll | C30: =SUM(I30:T30) | D30: =SUMIFS(qPL_Fact!$D:$D,qPL_Fact!$C:$C,$B30,qPL_Fact!$A:$A,D$3) | E30: =SUMIFS(qPL_Fact!$D:$D,qPL_Fact!$C:$C,$B30,qPL_Fact!$A:$A,E$3) | F30: =SUMIFS(qPL_Fact!$D:$D,qPL_Fact!$C:$C,$B30,qPL_Fact!$A:$A,F$3) | G30: =SUMIFS(qPL_Fact!$D:$D,qPL_Fact!$C:$C,$B30,qPL_Fact!$A:$A,G$3) | H30: =SUMIFS(qPL_Fact!$D:$D,qPL_Fact!$C:$C,$B30,qPL_Fact!$A:$A,H$3) | I30: =SUMIFS(qPL_Fact!$D:$D,qPL_Fact!$C:$C,$B30,qPL_Fact!$A:$A,I$3) | J30: =SUMIFS(qPL_Fact!$D:$D,qPL_Fact!$C:$C,$B30,qPL_Fact!$A:$A,J$3) | K30: =SUMIFS(qPL_Fact!$D:$D,qPL_Fact!$C:$C,$B30,qPL_Fact!$A:$A,K$3) | ... T30: =SUMIFS(qPL_Fact!$D:$D,qPL_Fact!$C:$C,$B30,qPL_Fact!$A:$A,T$3)
A31: 6003 | B31: Advertising | C31: =SUM(I31:T31) | D31: =SUMIFS(qPL_Fact!$D:$D,qPL_Fact!$C:$C,$B31,qPL_Fact!$A:$A,D$3) | E31: =SUMIFS(qPL_Fact!$D:$D,qPL_Fact!$C:$C,$B31,qPL_Fact!$A:$A,E$3) | F31: =SUMIFS(qPL_Fact!$D:$D,qPL_Fact!$C:$C,$B31,qPL_Fact!$A:$A,F$3) | G31: =SUMIFS(qPL_Fact!$D:$D,qPL_Fact!$C:$C,$B31,qPL_Fact!$A:$A,G$3) | H31: =SUMIFS(qPL_Fact!$D:$D,qPL_Fact!$C:$C,$B31,qPL_Fact!$A:$A,H$3) | I31: =SUMIFS(qPL_Fact!$D:$D,qPL_Fact!$C:$C,$B31,qPL_Fact!$A:$A,I$3) | J31: =SUMIFS(qPL_Fact!$D:$D,qPL_Fact!$C:$C,$B31,qPL_Fact!$A:$A,J$3) | K31: =SUMIFS(qPL_Fact!$D:$D,qPL_Fact!$C:$C,$B31,qPL_Fact!$A:$A,K$3) | ... T31: =SUMIFS(qPL_Fact!$D:$D,qPL_Fact!$C:$C,$B31,qPL_Fact!$A:$A,T$3)
A32: 6171 | B32: Electricity | C32: =SUM(I32:T32) | D32: =SUMIFS(qPL_Fact!$D:$D,qPL_Fact!$C:$C,$B32,qPL_Fact!$A:$A,D$3) | E32: =SUMIFS(qPL_Fact!$D:$D,qPL_Fact!$C:$C,$B32,qPL_Fact!$A:$A,E$3) | F32: =SUMIFS(qPL_Fact!$D:$D,qPL_Fact!$C:$C,$B32,qPL_Fact!$A:$A,F$3) | G32: =SUMIFS(qPL_Fact!$D:$D,qPL_Fact!$C:$C,$B32,qPL_Fact!$A:$A,G$3) | H32: =SUMIFS(qPL_Fact!$D:$D,qPL_Fact!$C:$C,$B32,qPL_Fact!$A:$A,H$3) | I32: =SUMIFS(qPL_Fact!$D:$D,qPL_Fact!$C:$C,$B32,qPL_Fact!$A:$A,I$3) | J32: =SUMIFS(qPL_Fact!$D:$D,qPL_Fact!$C:$C,$B32,qPL_Fact!$A:$A,J$3) | K32: =SUMIFS(qPL_Fact!$D:$D,qPL_Fact!$C:$C,$B32,qPL_Fact!$A:$A,K$3) | ... T32: =SUMIFS(qPL_Fact!$D:$D,qPL_Fact!$C:$C,$B32,qPL_Fact!$A:$A,T$3)
A33: 6172 | B33: Gas | C33: =SUM(I33:T33) | D33: =SUMIFS(qPL_Fact!$D:$D,qPL_Fact!$C:$C,$B33,qPL_Fact!$A:$A,D$3) | E33: =SUMIFS(qPL_Fact!$D:$D,qPL_Fact!$C:$C,$B33,qPL_Fact!$A:$A,E$3) | F33: =SUMIFS(qPL_Fact!$D:$D,qPL_Fact!$C:$C,$B33,qPL_Fact!$A:$A,F$3) | G33: =SUMIFS(qPL_Fact!$D:$D,qPL_Fact!$C:$C,$B33,qPL_Fact!$A:$A,G$3) | H33: =SUMIFS(qPL_Fact!$D:$D,qPL_Fact!$C:$C,$B33,qPL_Fact!$A:$A,H$3) | I33: =SUMIFS(qPL_Fact!$D:$D,qPL_Fact!$C:$C,$B33,qPL_Fact!$A:$A,I$3) | J33: =SUMIFS(qPL_Fact!$D:$D,qPL_Fact!$C:$C,$B33,qPL_Fact!$A:$A,J$3) | K33: =SUMIFS(qPL_Fact!$D:$D,qPL_Fact!$C:$C,$B33,qPL_Fact!$A:$A,K$3) | ... T33: =SUMIFS(qPL_Fact!$D:$D,qPL_Fact!$C:$C,$B33,qPL_Fact!$A:$A,T$3)
A34: 6173 | B34: Water | C34: =SUM(I34:T34) | D34: =SUMIFS(qPL_Fact!$D:$D,qPL_Fact!$C:$C,$B34,qPL_Fact!$A:$A,D$3) | E34: =SUMIFS(qPL_Fact!$D:$D,qPL_Fact!$C:$C,$B34,qPL_Fact!$A:$A,E$3) | F34: =SUMIFS(qPL_Fact!$D:$D,qPL_Fact!$C:$C,$B34,qPL_Fact!$A:$A,F$3) | G34: =SUMIFS(qPL_Fact!$D:$D,qPL_Fact!$C:$C,$B34,qPL_Fact!$A:$A,G$3) | H34: =SUMIFS(qPL_Fact!$D:$D,qPL_Fact!$C:$C,$B34,qPL_Fact!$A:$A,H$3) | I34: =SUMIFS(qPL_Fact!$D:$D,qPL_Fact!$C:$C,$B34,qPL_Fact!$A:$A,I$3) | J34: =SUMIFS(qPL_Fact!$D:$D,qPL_Fact!$C:$C,$B34,qPL_Fact!$A:$A,J$3) | K34: =SUMIFS(qPL_Fact!$D:$D,qPL_Fact!$C:$C,$B34,qPL_Fact!$A:$A,K$3) | ... T34: =SUMIFS(qPL_Fact!$D:$D,qPL_Fact!$C:$C,$B34,qPL_Fact!$A:$A,T$3)
A35: 6175 | B35: Garbage & Recycling | C35: =SUM(I35:T35) | D35: =SUMIFS(qPL_Fact!$D:$D,qPL_Fact!$C:$C,$B35,qPL_Fact!$A:$A,D$3) | E35: =SUMIFS(qPL_Fact!$D:$D,qPL_Fact!$C:$C,$B35,qPL_Fact!$A:$A,E$3) | F35: =SUMIFS(qPL_Fact!$D:$D,qPL_Fact!$C:$C,$B35,qPL_Fact!$A:$A,F$3) | G35: =SUMIFS(qPL_Fact!$D:$D,qPL_Fact!$C:$C,$B35,qPL_Fact!$A:$A,G$3) | H35: =SUMIFS(qPL_Fact!$D:$D,qPL_Fact!$C:$C,$B35,qPL_Fact!$A:$A,H$3) | I35: =SUMIFS(qPL_Fact!$D:$D,qPL_Fact!$C:$C,$B35,qPL_Fact!$A:$A,I$3) | J35: =SUMIFS(qPL_Fact!$D:$D,qPL_Fact!$C:$C,$B35,qPL_Fact!$A:$A,J$3) | K35: =SUMIFS(qPL_Fact!$D:$D,qPL_Fact!$C:$C,$B35,qPL_Fact!$A:$A,K$3) | ... T35: =SUMIFS(qPL_Fact!$D:$D,qPL_Fact!$C:$C,$B35,qPL_Fact!$A:$A,T$3)
A36: 6176 | B36: Internet | C36: =SUM(I36:T36) | D36: =SUMIFS(qPL_Fact!$D:$D,qPL_Fact!$C:$C,$B36,qPL_Fact!$A:$A,D$3) | E36: =SUMIFS(qPL_Fact!$D:$D,qPL_Fact!$C:$C,$B36,qPL_Fact!$A:$A,E$3) | F36: =SUMIFS(qPL_Fact!$D:$D,qPL_Fact!$C:$C,$B36,qPL_Fact!$A:$A,F$3) | G36: =SUMIFS(qPL_Fact!$D:$D,qPL_Fact!$C:$C,$B36,qPL_Fact!$A:$A,G$3) | H36: =SUMIFS(qPL_Fact!$D:$D,qPL_Fact!$C:$C,$B36,qPL_Fact!$A:$A,H$3) | I36: =SUMIFS(qPL_Fact!$D:$D,qPL_Fact!$C:$C,$B36,qPL_Fact!$A:$A,I$3) | J36: =SUMIFS(qPL_Fact!$D:$D,qPL_Fact!$C:$C,$B36,qPL_Fact!$A:$A,J$3) | K36: =SUMIFS(qPL_Fact!$D:$D,qPL_Fact!$C:$C,$B36,qPL_Fact!$A:$A,K$3) | ... T36: =SUMIFS(qPL_Fact!$D:$D,qPL_Fact!$C:$C,$B36,qPL_Fact!$A:$A,T$3)
A37: 6111 | B37: Management Fee (4%) | C37: =SUM(I37:T37) | D37: =SUMIFS(qPL_Fact!$D:$D,qPL_Fact!$C:$C,$B37,qPL_Fact!$A:$A,D$3) | E37: =SUMIFS(qPL_Fact!$D:$D,qPL_Fact!$C:$C,$B37,qPL_Fact!$A:$A,E$3) | F37: =SUMIFS(qPL_Fact!$D:$D,qPL_Fact!$C:$C,$B37,qPL_Fact!$A:$A,F$3) | G37: =SUMIFS(qPL_Fact!$D:$D,qPL_Fact!$C:$C,$B37,qPL_Fact!$A:$A,G$3) | H37: =SUMIFS(qPL_Fact!$D:$D,qPL_Fact!$C:$C,$B37,qPL_Fact!$A:$A,H$3) | I37: =SUMIFS(qPL_Fact!$D:$D,qPL_Fact!$C:$C,$B37,qPL_Fact!$A:$A,I$3) | J37: =SUMIFS(qPL_Fact!$D:$D,qPL_Fact!$C:$C,$B37,qPL_Fact!$A:$A,J$3) | K37: =SUMIFS(qPL_Fact!$D:$D,qPL_Fact!$C:$C,$B37,qPL_Fact!$A:$A,K$3) | ... T37: =SUMIFS(qPL_Fact!$D:$D,qPL_Fact!$C:$C,$B37,qPL_Fact!$A:$A,T$3)
A38: 6073 | B38: General Maint. Labor | C38: =SUM(I38:T38) | D38: =SUMIFS(qPL_Fact!$D:$D,qPL_Fact!$C:$C,$B38,qPL_Fact!$A:$A,D$3) | E38: =SUMIFS(qPL_Fact!$D:$D,qPL_Fact!$C:$C,$B38,qPL_Fact!$A:$A,E$3) | F38: =SUMIFS(qPL_Fact!$D:$D,qPL_Fact!$C:$C,$B38,qPL_Fact!$A:$A,F$3) | G38: =SUMIFS(qPL_Fact!$D:$D,qPL_Fact!$C:$C,$B38,qPL_Fact!$A:$A,G$3) | H38: =SUMIFS(qPL_Fact!$D:$D,qPL_Fact!$C:$C,$B38,qPL_Fact!$A:$A,H$3) | I38: =SUMIFS(qPL_Fact!$D:$D,qPL_Fact!$C:$C,$B38,qPL_Fact!$A:$A,I$3) | J38: =SUMIFS(qPL_Fact!$D:$D,qPL_Fact!$C:$C,$B38,qPL_Fact!$A:$A,J$3) | K38: =SUMIFS(qPL_Fact!$D:$D,qPL_Fact!$C:$C,$B38,qPL_Fact!$A:$A,K$3) | ... T38: =SUMIFS(qPL_Fact!$D:$D,qPL_Fact!$C:$C,$B38,qPL_Fact!$A:$A,T$3)
A39: 6074 | B39: Landscaping | C39: =SUM(I39:T39) | D39: =SUMIFS(qPL_Fact!$D:$D,qPL_Fact!$C:$C,$B39,qPL_Fact!$A:$A,D$3) | E39: =SUMIFS(qPL_Fact!$D:$D,qPL_Fact!$C:$C,$B39,qPL_Fact!$A:$A,E$3) | F39: =SUMIFS(qPL_Fact!$D:$D,qPL_Fact!$C:$C,$B39,qPL_Fact!$A:$A,F$3) | G39: =SUMIFS(qPL_Fact!$D:$D,qPL_Fact!$C:$C,$B39,qPL_Fact!$A:$A,G$3) | H39: =SUMIFS(qPL_Fact!$D:$D,qPL_Fact!$C:$C,$B39,qPL_Fact!$A:$A,H$3) | I39: =SUMIFS(qPL_Fact!$D:$D,qPL_Fact!$C:$C,$B39,qPL_Fact!$A:$A,I$3) | J39: =SUMIFS(qPL_Fact!$D:$D,qPL_Fact!$C:$C,$B39,qPL_Fact!$A:$A,J$3) | K39: =SUMIFS(qPL_Fact!$D:$D,qPL_Fact!$C:$C,$B39,qPL_Fact!$A:$A,K$3) | ... T39: =SUMIFS(qPL_Fact!$D:$D,qPL_Fact!$C:$C,$B39,qPL_Fact!$A:$A,T$3)
... A59: 6179 | B59: Asset Mgmt Fee | C59: =SUM(I59:T59) | D59: =SUMIFS(qPL_Fact!$D:$D,qPL_Fact!$C:$C,$B59,qPL_Fact!$A:$A,D$3) | E59: =SUMIFS(qPL_Fact!$D:$D,qPL_Fact!$C:$C,$B59,qPL_Fact!$A:$A,E$3) | F59: =SUMIFS(qPL_Fact!$D:$D,qPL_Fact!$C:$C,$B59,qPL_Fact!$A:$A,F$3) | G59: =SUMIFS(qPL_Fact!$D:$D,qPL_Fact!$C:$C,$B59,qPL_Fact!$A:$A,G$3) | H59: =SUMIFS(qPL_Fact!$D:$D,qPL_Fact!$C:$C,$B59,qPL_Fact!$A:$A,H$3) | I59: =SUMIFS(qPL_Fact!$D:$D,qPL_Fact!$C:$C,$B59,qPL_Fact!$A:$A,I$3) | J59: =SUMIFS(qPL_Fact!$D:$D,qPL_Fact!$C:$C,$B59,qPL_Fact!$A:$A,J$3) | K59: =SUMIFS(qPL_Fact!$D:$D,qPL_Fact!$C:$C,$B59,qPL_Fact!$A:$A,K$3) | ... T59: =SUMIFS(qPL_Fact!$D:$D,qPL_Fact!$C:$C,$B59,qPL_Fact!$A:$A,T$3)
B60: Total Operating Expenses | C60: =SUM(I60:T60) | D60: =SUMIFS(qPL_Fact!$D:$D,qPL_Fact!$C:$C,$B60,qPL_Fact!$A:$A,D$3) | E60: =SUMIFS(qPL_Fact!$D:$D,qPL_Fact!$C:$C,$B60,qPL_Fact!$A:$A,E$3) | F60: =SUMIFS(qPL_Fact!$D:$D,qPL_Fact!$C:$C,$B60,qPL_Fact!$A:$A,F$3) | G60: =SUMIFS(qPL_Fact!$D:$D,qPL_Fact!$C:$C,$B60,qPL_Fact!$A:$A,G$3) | H60: =SUMIFS(qPL_Fact!$D:$D,qPL_Fact!$C:$C,$B60,qPL_Fact!$A:$A,H$3) | I60: =SUMIFS(qPL_Fact!$D:$D,qPL_Fact!$C:$C,$B60,qPL_Fact!$A:$A,I$3) | J60: =SUMIFS(qPL_Fact!$D:$D,qPL_Fact!$C:$C,$B60,qPL_Fact!$A:$A,J$3) | K60: =SUMIFS(qPL_Fact!$D:$D,qPL_Fact!$C:$C,$B60,qPL_Fact!$A:$A,K$3) | ... T60: =SUMIFS(qPL_Fact!$D:$D,qPL_Fact!$C:$C,$B60,qPL_Fact!$A:$A,T$3)
B62: NET OPERATING INCOME (NOI) | C62: =SUM(I62:T62) | D62: =SUMIFS(qPL_Fact!$D:$D,qPL_Fact!$C:$C,$B62,qPL_Fact!$A:$A,D$3) | E62: =SUMIFS(qPL_Fact!$D:$D,qPL_Fact!$C:$C,$B62,qPL_Fact!$A:$A,E$3) | F62: =SUMIFS(qPL_Fact!$D:$D,qPL_Fact!$C:$C,$B62,qPL_Fact!$A:$A,F$3) | G62: =SUMIFS(qPL_Fact!$D:$D,qPL_Fact!$C:$C,$B62,qPL_Fact!$A:$A,G$3) | H62: =SUMIFS(qPL_Fact!$D:$D,qPL_Fact!$C:$C,$B62,qPL_Fact!$A:$A,H$3) | I62: =SUMIFS(qPL_Fact!$D:$D,qPL_Fact!$C:$C,$B62,qPL_Fact!$A:$A,I$3) | J62: =SUMIFS(qPL_Fact!$D:$D,qPL_Fact!$C:$C,$B62,qPL_Fact!$A:$A,J$3) | K62: =SUMIFS(qPL_Fact!$D:$D,qPL_Fact!$C:$C,$B62,qPL_Fact!$A:$A,K$3) | ... T62: =SUMIFS(qPL_Fact!$D:$D,qPL_Fact!$C:$C,$B62,qPL_Fact!$A:$A,T$3)
B64: DEBT SERVICE | C64: =SUM(I64:T64) | D64: =SUMIFS(qPL_Fact!$D:$D,qPL_Fact!$C:$C,$B64,qPL_Fact!$A:$A,D$3) | E64: =SUMIFS(qPL_Fact!$D:$D,qPL_Fact!$C:$C,$B64,qPL_Fact!$A:$A,E$3) | F64: =SUMIFS(qPL_Fact!$D:$D,qPL_Fact!$C:$C,$B64,qPL_Fact!$A:$A,F$3) | G64: =SUMIFS(qPL_Fact!$D:$D,qPL_Fact!$C:$C,$B64,qPL_Fact!$A:$A,G$3) | H64: =SUMIFS(qPL_Fact!$D:$D,qPL_Fact!$C:$C,$B64,qPL_Fact!$A:$A,H$3) | I64: =SUMIFS(qPL_Fact!$D:$D,qPL_Fact!$C:$C,$B64,qPL_Fact!$A:$A,I$3) | J64: =SUMIFS(qPL_Fact!$D:$D,qPL_Fact!$C:$C,$B64,qPL_Fact!$A:$A,J$3) | K64: =SUMIFS(qPL_Fact!$D:$D,qPL_Fact!$C:$C,$B64,qPL_Fact!$A:$A,K$3) | ... T64: =SUMIFS(qPL_Fact!$D:$D,qPL_Fact!$C:$C,$B64,qPL_Fact!$A:$A,T$3)
...

Sheet T12_PL
A1: The Groves Apartments | Trailing 12-Month P&L
A2: Jan 2025 – Dec 2025 | 6800-6810 63rd Ave N, Brooklyn Park MN 55443
A3: GL | B3: Account | C3: 45658 | D3: 45689 | E3: 45717 | F3: 45748 | G3: 45778 | H3: 45809 | I3: 45839 | J3: 45870 | K3: 45901 | L3: 45931 | M3: 45962 | N3: 45992 | O3: T12 Total
B4: REVENUE | C4: =SUMIFS(qPL_Fact!$D:$D,qPL_Fact!$C:$C,$B4,qPL_Fact!$A:$A,C$3) | D4: =SUMIFS(qPL_Fact!$D:$D,qPL_Fact!$C:$C,$B4,qPL_Fact!$A:$A,D$3) | E4: =SUMIFS(qPL_Fact!$D:$D,qPL_Fact!$C:$C,$B4,qPL_Fact!$A:$A,E$3) | F4: =SUMIFS(qPL_Fact!$D:$D,qPL_Fact!$C:$C,$B4,qPL_Fact!$A:$A,F$3) | G4: =SUMIFS(qPL_Fact!$D:$D,qPL_Fact!$C:$C,$B4,qPL_Fact!$A:$A,G$3) | H4: =SUMIFS(qPL_Fact!$D:$D,qPL_Fact!$C:$C,$B4,qPL_Fact!$A:$A,H$3) | I4: =SUMIFS(qPL_Fact!$D:$D,qPL_Fact!$C:$C,$B4,qPL_Fact!$A:$A,I$3) | J4: =SUMIFS(qPL_Fact!$D:$D,qPL_Fact!$C:$C,$B4,qPL_Fact!$A:$A,J$3) | ... N4: =SUMIFS(qPL_Fact!$D:$D,qPL_Fact!$C:$C,$B4,qPL_Fact!$A:$A,N$3) | O4: =SUM(C4:N4)
A5: 3090 | B5: Gross Potential Rent | C5: =SUMIFS(qPL_Fact!$D:$D,qPL_Fact!$C:$C,$B5,qPL_Fact!$A:$A,C$3) | D5: =SUMIFS(qPL_Fact!$D:$D,qPL_Fact!$C:$C,$B5,qPL_Fact!$A:$A,D$3) | E5: =SUMIFS(qPL_Fact!$D:$D,qPL_Fact!$C:$C,$B5,qPL_Fact!$A:$A,E$3) | F5: =SUMIFS(qPL_Fact!$D:$D,qPL_Fact!$C:$C,$B5,qPL_Fact!$A:$A,F$3) | G5: =SUMIFS(qPL_Fact!$D:$D,qPL_Fact!$C:$C,$B5,qPL_Fact!$A:$A,G$3) | H5: =SUMIFS(qPL_Fact!$D:$D,qPL_Fact!$C:$C,$B5,qPL_Fact!$A:$A,H$3) | I5: =SUMIFS(qPL_Fact!$D:$D,qPL_Fact!$C:$C,$B5,qPL_Fact!$A:$A,I$3) | J5: =SUMIFS(qPL_Fact!$D:$D,qPL_Fact!$C:$C,$B5,qPL_Fact!$A:$A,J$3) | ... N5: =SUMIFS(qPL_Fact!$D:$D,qPL_Fact!$C:$C,$B5,qPL_Fact!$A:$A,N$3) | O5: =SUM(C5:N5)
A6: 4100 | B6: Loss/Gain to Market | C6: =SUMIFS(qPL_Fact!$D:$D,qPL_Fact!$C:$C,$B6,qPL_Fact!$A:$A,C$3) | D6: =SUMIFS(qPL_Fact!$D:$D,qPL_Fact!$C:$C,$B6,qPL_Fact!$A:$A,D$3) | E6: =SUMIFS(qPL_Fact!$D:$D,qPL_Fact!$C:$C,$B6,qPL_Fact!$A:$A,E$3) | F6: =SUMIFS(qPL_Fact!$D:$D,qPL_Fact!$C:$C,$B6,qPL_Fact!$A:$A,F$3) | G6: =SUMIFS(qPL_Fact!$D:$D,qPL_Fact!$C:$C,$B6,qPL_Fact!$A:$A,G$3) | H6: =SUMIFS(qPL_Fact!$D:$D,qPL_Fact!$C:$C,$B6,qPL_Fact!$A:$A,H$3) | I6: =SUMIFS(qPL_Fact!$D:$D,qPL_Fact!$C:$C,$B6,qPL_Fact!$A:$A,I$3) | J6: =SUMIFS(qPL_Fact!$D:$D,qPL_Fact!$C:$C,$B6,qPL_Fact!$A:$A,J$3) | ... N6: =SUMIFS(qPL_Fact!$D:$D,qPL_Fact!$C:$C,$B6,qPL_Fact!$A:$A,N$3) | O6: =SUM(C6:N6)
A7: 4100 | B7: Delinquency | C7: =SUMIFS(qPL_Fact!$D:$D,qPL_Fact!$C:$C,$B7,qPL_Fact!$A:$A,C$3) | D7: =SUMIFS(qPL_Fact!$D:$D,qPL_Fact!$C:$C,$B7,qPL_Fact!$A:$A,D$3) | E7: =SUMIFS(qPL_Fact!$D:$D,qPL_Fact!$C:$C,$B7,qPL_Fact!$A:$A,E$3) | F7: =SUMIFS(qPL_Fact!$D:$D,qPL_Fact!$C:$C,$B7,qPL_Fact!$A:$A,F$3) | G7: =SUMIFS(qPL_Fact!$D:$D,qPL_Fact!$C:$C,$B7,qPL_Fact!$A:$A,G$3) | H7: =SUMIFS(qPL_Fact!$D:$D,qPL_Fact!$C:$C,$B7,qPL_Fact!$A:$A,H$3) | I7: =SUMIFS(qPL_Fact!$D:$D,qPL_Fact!$C:$C,$B7,qPL_Fact!$A:$A,I$3) | J7: =SUMIFS(qPL_Fact!$D:$D,qPL_Fact!$C:$C,$B7,qPL_Fact!$A:$A,J$3) | ... N7: =SUMIFS(qPL_Fact!$D:$D,qPL_Fact!$C:$C,$B7,qPL_Fact!$A:$A,N$3) | O7: =SUM(C7:N7)
A8: 4100 | B8: Vacancy | C8: =SUMIFS(qPL_Fact!$D:$D,qPL_Fact!$C:$C,$B8,qPL_Fact!$A:$A,C$3) | D8: =SUMIFS(qPL_Fact!$D:$D,qPL_Fact!$C:$C,$B8,qPL_Fact!$A:$A,D$3) | E8: =SUMIFS(qPL_Fact!$D:$D,qPL_Fact!$C:$C,$B8,qPL_Fact!$A:$A,E$3) | F8: =SUMIFS(qPL_Fact!$D:$D,qPL_Fact!$C:$C,$B8,qPL_Fact!$A:$A,F$3) | G8: =SUMIFS(qPL_Fact!$D:$D,qPL_Fact!$C:$C,$B8,qPL_Fact!$A:$A,G$3) | H8: =SUMIFS(qPL_Fact!$D:$D,qPL_Fact!$C:$C,$B8,qPL_Fact!$A:$A,H$3) | I8: =SUMIFS(qPL_Fact!$D:$D,qPL_Fact!$C:$C,$B8,qPL_Fact!$A:$A,I$3) | J8: =SUMIFS(qPL_Fact!$D:$D,qPL_Fact!$C:$C,$B8,qPL_Fact!$A:$A,J$3) | ... N8: =SUMIFS(qPL_Fact!$D:$D,qPL_Fact!$C:$C,$B8,qPL_Fact!$A:$A,N$3) | O8: =SUM(C8:N8)
B9: Concessions | C9: =SUMIFS(qPL_Fact!$D:$D,qPL_Fact!$C:$C,$B9,qPL_Fact!$A:$A,C$3) | D9: =SUMIFS(qPL_Fact!$D:$D,qPL_Fact!$C:$C,$B9,qPL_Fact!$A:$A,D$3) | E9: =SUMIFS(qPL_Fact!$D:$D,qPL_Fact!$C:$C,$B9,qPL_Fact!$A:$A,E$3) | F9: =SUMIFS(qPL_Fact!$D:$D,qPL_Fact!$C:$C,$B9,qPL_Fact!$A:$A,F$3) | G9: =SUMIFS(qPL_Fact!$D:$D,qPL_Fact!$C:$C,$B9,qPL_Fact!$A:$A,G$3) | H9: =SUMIFS(qPL_Fact!$D:$D,qPL_Fact!$C:$C,$B9,qPL_Fact!$A:$A,H$3) | I9: =SUMIFS(qPL_Fact!$D:$D,qPL_Fact!$C:$C,$B9,qPL_Fact!$A:$A,I$3) | J9: =SUMIFS(qPL_Fact!$D:$D,qPL_Fact!$C:$C,$B9,qPL_Fact!$A:$A,J$3) | ... N9: =SUMIFS(qPL_Fact!$D:$D,qPL_Fact!$C:$C,$B9,qPL_Fact!$A:$A,N$3) | O9: =SUM(C9:N9)
A10: 4700 | B10: Other Rent Adjustments | C10: =SUMIFS(qPL_Fact!$D:$D,qPL_Fact!$C:$C,$B10,qPL_Fact!$A:$A,C$3) | D10: =SUMIFS(qPL_Fact!$D:$D,qPL_Fact!$C:$C,$B10,qPL_Fact!$A:$A,D$3) | E10: =SUMIFS(qPL_Fact!$D:$D,qPL_Fact!$C:$C,$B10,qPL_Fact!$A:$A,E$3) | F10: =SUMIFS(qPL_Fact!$D:$D,qPL_Fact!$C:$C,$B10,qPL_Fact!$A:$A,F$3) | G10: =SUMIFS(qPL_Fact!$D:$D,qPL_Fact!$C:$C,$B10,qPL_Fact!$A:$A,G$3) | H10: =SUMIFS(qPL_Fact!$D:$D,qPL_Fact!$C:$C,$B10,qPL_Fact!$A:$A,H$3) | I10: =SUMIFS(qPL_Fact!$D:$D,qPL_Fact!$C:$C,$B10,qPL_Fact!$A:$A,I$3) | J10: =SUMIFS(qPL_Fact!$D:$D,qPL_Fact!$C:$C,$B10,qPL_Fact!$A:$A,J$3) | ... N10: =SUMIFS(qPL_Fact!$D:$D,qPL_Fact!$C:$C,$B10,qPL_Fact!$A:$A,N$3) | O10: =SUM(C10:N10)
B11: Effective Rental Income | C11: =SUMIFS(qPL_Fact!$D:$D,qPL_Fact!$C:$C,$B11,qPL_Fact!$A:$A,C$3) | D11: =SUMIFS(qPL_Fact!$D:$D,qPL_Fact!$C:$C,$B11,qPL_Fact!$A:$A,D$3) | E11: =SUMIFS(qPL_Fact!$D:$D,qPL_Fact!$C:$C,$B11,qPL_Fact!$A:$A,E$3) | F11: =SUMIFS(qPL_Fact!$D:$D,qPL_Fact!$C:$C,$B11,qPL_Fact!$A:$A,F$3) | G11: =SUMIFS(qPL_Fact!$D:$D,qPL_Fact!$C:$C,$B11,qPL_Fact!$A:$A,G$3) | H11: =SUMIFS(qPL_Fact!$D:$D,qPL_Fact!$C:$C,$B11,qPL_Fact!$A:$A,H$3) | I11: =SUMIFS(qPL_Fact!$D:$D,qPL_Fact!$C:$C,$B11,qPL_Fact!$A:$A,I$3) | J11: =SUMIFS(qPL_Fact!$D:$D,qPL_Fact!$C:$C,$B11,qPL_Fact!$A:$A,J$3) | ... N11: =SUMIFS(qPL_Fact!$D:$D,qPL_Fact!$C:$C,$B11,qPL_Fact!$A:$A,N$3) | O11: =SUM(C11:N11)
B13: OTHER INCOME | C13: =SUMIFS(qPL_Fact!$D:$D,qPL_Fact!$C:$C,$B13,qPL_Fact!$A:$A,C$3) | D13: =SUMIFS(qPL_Fact!$D:$D,qPL_Fact!$C:$C,$B13,qPL_Fact!$A:$A,D$3) | E13: =SUMIFS(qPL_Fact!$D:$D,qPL_Fact!$C:$C,$B13,qPL_Fact!$A:$A,E$3) | F13: =SUMIFS(qPL_Fact!$D:$D,qPL_Fact!$C:$C,$B13,qPL_Fact!$A:$A,F$3) | G13: =SUMIFS(qPL_Fact!$D:$D,qPL_Fact!$C:$C,$B13,qPL_Fact!$A:$A,G$3) | H13: =SUMIFS(qPL_Fact!$D:$D,qPL_Fact!$C:$C,$B13,qPL_Fact!$A:$A,H$3) | I13: =SUMIFS(qPL_Fact!$D:$D,qPL_Fact!$C:$C,$B13,qPL_Fact!$A:$A,I$3) | J13: =SUMIFS(qPL_Fact!$D:$D,qPL_Fact!$C:$C,$B13,qPL_Fact!$A:$A,J$3) | ... N13: =SUMIFS(qPL_Fact!$D:$D,qPL_Fact!$C:$C,$B13,qPL_Fact!$A:$A,N$3) | O13: =SUM(C13:N13)
A14: 4460 | B14: Late Fees | C14: =SUMIFS(qPL_Fact!$D:$D,qPL_Fact!$C:$C,$B14,qPL_Fact!$A:$A,C$3) | D14: =SUMIFS(qPL_Fact!$D:$D,qPL_Fact!$C:$C,$B14,qPL_Fact!$A:$A,D$3) | E14: =SUMIFS(qPL_Fact!$D:$D,qPL_Fact!$C:$C,$B14,qPL_Fact!$A:$A,E$3) | F14: =SUMIFS(qPL_Fact!$D:$D,qPL_Fact!$C:$C,$B14,qPL_Fact!$A:$A,F$3) | G14: =SUMIFS(qPL_Fact!$D:$D,qPL_Fact!$C:$C,$B14,qPL_Fact!$A:$A,G$3) | H14: =SUMIFS(qPL_Fact!$D:$D,qPL_Fact!$C:$C,$B14,qPL_Fact!$A:$A,H$3) | I14: =SUMIFS(qPL_Fact!$D:$D,qPL_Fact!$C:$C,$B14,qPL_Fact!$A:$A,I$3) | J14: =SUMIFS(qPL_Fact!$D:$D,qPL_Fact!$C:$C,$B14,qPL_Fact!$A:$A,J$3) | ... N14: =SUMIFS(qPL_Fact!$D:$D,qPL_Fact!$C:$C,$B14,qPL_Fact!$A:$A,N$3) | O14: =SUM(C14:N14)
A15: 4490 | B15: Move-In Fees | C15: =SUMIFS(qPL_Fact!$D:$D,qPL_Fact!$C:$C,$B15,qPL_Fact!$A:$A,C$3) | D15: =SUMIFS(qPL_Fact!$D:$D,qPL_Fact!$C:$C,$B15,qPL_Fact!$A:$A,D$3) | E15: =SUMIFS(qPL_Fact!$D:$D,qPL_Fact!$C:$C,$B15,qPL_Fact!$A:$A,E$3) | F15: =SUMIFS(qPL_Fact!$D:$D,qPL_Fact!$C:$C,$B15,qPL_Fact!$A:$A,F$3) | G15: =SUMIFS(qPL_Fact!$D:$D,qPL_Fact!$C:$C,$B15,qPL_Fact!$A:$A,G$3) | H15: =SUMIFS(qPL_Fact!$D:$D,qPL_Fact!$C:$C,$B15,qPL_Fact!$A:$A,H$3) | I15: =SUMIFS(qPL_Fact!$D:$D,qPL_Fact!$C:$C,$B15,qPL_Fact!$A:$A,I$3) | J15: =SUMIFS(qPL_Fact!$D:$D,qPL_Fact!$C:$C,$B15,qPL_Fact!$A:$A,J$3) | ... N15: =SUMIFS(qPL_Fact!$D:$D,qPL_Fact!$C:$C,$B15,qPL_Fact!$A:$A,N$3) | O15: =SUM(C15:N15)
A16: 4440 | B16: Application Fees | C16: =SUMIFS(qPL_Fact!$D:$D,qPL_Fact!$C:$C,$B16,qPL_Fact!$A:$A,C$3) | D16: =SUMIFS(qPL_Fact!$D:$D,qPL_Fact!$C:$C,$B16,qPL_Fact!$A:$A,D$3) | E16: =SUMIFS(qPL_Fact!$D:$D,qPL_Fact!$C:$C,$B16,qPL_Fact!$A:$A,E$3) | F16: =SUMIFS(qPL_Fact!$D:$D,qPL_Fact!$C:$C,$B16,qPL_Fact!$A:$A,F$3) | G16: =SUMIFS(qPL_Fact!$D:$D,qPL_Fact!$C:$C,$B16,qPL_Fact!$A:$A,G$3) | H16: =SUMIFS(qPL_Fact!$D:$D,qPL_Fact!$C:$C,$B16,qPL_Fact!$A:$A,H$3) | I16: =SUMIFS(qPL_Fact!$D:$D,qPL_Fact!$C:$C,$B16,qPL_Fact!$A:$A,I$3) | J16: =SUMIFS(qPL_Fact!$D:$D,qPL_Fact!$C:$C,$B16,qPL_Fact!$A:$A,J$3) | ... N16: =SUMIFS(qPL_Fact!$D:$D,qPL_Fact!$C:$C,$B16,qPL_Fact!$A:$A,N$3) | O16: =SUM(C16:N16)
A17: 4415 | B17: Internet Charges | C17: =SUMIFS(qPL_Fact!$D:$D,qPL_Fact!$C:$C,$B17,qPL_Fact!$A:$A,C$3) | D17: =SUMIFS(qPL_Fact!$D:$D,qPL_Fact!$C:$C,$B17,qPL_Fact!$A:$A,D$3) | E17: =SUMIFS(qPL_Fact!$D:$D,qPL_Fact!$C:$C,$B17,qPL_Fact!$A:$A,E$3) | F17: =SUMIFS(qPL_Fact!$D:$D,qPL_Fact!$C:$C,$B17,qPL_Fact!$A:$A,F$3) | G17: =SUMIFS(qPL_Fact!$D:$D,qPL_Fact!$C:$C,$B17,qPL_Fact!$A:$A,G$3) | H17: =SUMIFS(qPL_Fact!$D:$D,qPL_Fact!$C:$C,$B17,qPL_Fact!$A:$A,H$3) | I17: =SUMIFS(qPL_Fact!$D:$D,qPL_Fact!$C:$C,$B17,qPL_Fact!$A:$A,I$3) | J17: =SUMIFS(qPL_Fact!$D:$D,qPL_Fact!$C:$C,$B17,qPL_Fact!$A:$A,J$3) | ... N17: =SUMIFS(qPL_Fact!$D:$D,qPL_Fact!$C:$C,$B17,qPL_Fact!$A:$A,N$3) | O17: =SUM(C17:N17)
A18: 4450 | B18: Insurance Services | C18: =SUMIFS(qPL_Fact!$D:$D,qPL_Fact!$C:$C,$B18,qPL_Fact!$A:$A,C$3) | D18: =SUMIFS(qPL_Fact!$D:$D,qPL_Fact!$C:$C,$B18,qPL_Fact!$A:$A,D$3) | E18: =SUMIFS(qPL_Fact!$D:$D,qPL_Fact!$C:$C,$B18,qPL_Fact!$A:$A,E$3) | F18: =SUMIFS(qPL_Fact!$D:$D,qPL_Fact!$C:$C,$B18,qPL_Fact!$A:$A,F$3) | G18: =SUMIFS(qPL_Fact!$D:$D,qPL_Fact!$C:$C,$B18,qPL_Fact!$A:$A,G$3) | H18: =SUMIFS(qPL_Fact!$D:$D,qPL_Fact!$C:$C,$B18,qPL_Fact!$A:$A,H$3) | I18: =SUMIFS(qPL_Fact!$D:$D,qPL_Fact!$C:$C,$B18,qPL_Fact!$A:$A,I$3) | J18: =SUMIFS(qPL_Fact!$D:$D,qPL_Fact!$C:$C,$B18,qPL_Fact!$A:$A,J$3) | ... N18: =SUMIFS(qPL_Fact!$D:$D,qPL_Fact!$C:$C,$B18,qPL_Fact!$A:$A,N$3) | O18: =SUM(C18:N18)
B19: Interest Income | C19: =SUMIFS(qPL_Fact!$D:$D,qPL_Fact!$C:$C,$B19,qPL_Fact!$A:$A,C$3) | D19: =SUMIFS(qPL_Fact!$D:$D,qPL_Fact!$C:$C,$B19,qPL_Fact!$A:$A,D$3) | E19: =SUMIFS(qPL_Fact!$D:$D,qPL_Fact!$C:$C,$B19,qPL_Fact!$A:$A,E$3) | F19: =SUMIFS(qPL_Fact!$D:$D,qPL_Fact!$C:$C,$B19,qPL_Fact!$A:$A,F$3) | G19: =SUMIFS(qPL_Fact!$D:$D,qPL_Fact!$C:$C,$B19,qPL_Fact!$A:$A,G$3) | H19: =SUMIFS(qPL_Fact!$D:$D,qPL_Fact!$C:$C,$B19,qPL_Fact!$A:$A,H$3) | I19: =SUMIFS(qPL_Fact!$D:$D,qPL_Fact!$C:$C,$B19,qPL_Fact!$A:$A,I$3) | J19: =SUMIFS(qPL_Fact!$D:$D,qPL_Fact!$C:$C,$B19,qPL_Fact!$A:$A,J$3) | ... N19: =SUMIFS(qPL_Fact!$D:$D,qPL_Fact!$C:$C,$B19,qPL_Fact!$A:$A,N$3) | O19: =SUM(C19:N19)
A20: 4730 | B20: Utility Reimbursement | C20: =SUMIFS(qPL_Fact!$D:$D,qPL_Fact!$C:$C,$B20,qPL_Fact!$A:$A,C$3) | D20: =SUMIFS(qPL_Fact!$D:$D,qPL_Fact!$C:$C,$B20,qPL_Fact!$A:$A,D$3) | E20: =SUMIFS(qPL_Fact!$D:$D,qPL_Fact!$C:$C,$B20,qPL_Fact!$A:$A,E$3) | F20: =SUMIFS(qPL_Fact!$D:$D,qPL_Fact!$C:$C,$B20,qPL_Fact!$A:$A,F$3) | G20: =SUMIFS(qPL_Fact!$D:$D,qPL_Fact!$C:$C,$B20,qPL_Fact!$A:$A,G$3) | H20: =SUMIFS(qPL_Fact!$D:$D,qPL_Fact!$C:$C,$B20,qPL_Fact!$A:$A,H$3) | I20: =SUMIFS(qPL_Fact!$D:$D,qPL_Fact!$C:$C,$B20,qPL_Fact!$A:$A,I$3) | J20: =SUMIFS(qPL_Fact!$D:$D,qPL_Fact!$C:$C,$B20,qPL_Fact!$A:$A,J$3) | ... N20: =SUMIFS(qPL_Fact!$D:$D,qPL_Fact!$C:$C,$B20,qPL_Fact!$A:$A,N$3) | O20: =SUM(C20:N20)
B21: Deposit Forfeit | C21: =SUMIFS(qPL_Fact!$D:$D,qPL_Fact!$C:$C,$B21,qPL_Fact!$A:$A,C$3) | D21: =SUMIFS(qPL_Fact!$D:$D,qPL_Fact!$C:$C,$B21,qPL_Fact!$A:$A,D$3) | E21: =SUMIFS(qPL_Fact!$D:$D,qPL_Fact!$C:$C,$B21,qPL_Fact!$A:$A,E$3) | F21: =SUMIFS(qPL_Fact!$D:$D,qPL_Fact!$C:$C,$B21,qPL_Fact!$A:$A,F$3) | G21: =SUMIFS(qPL_Fact!$D:$D,qPL_Fact!$C:$C,$B21,qPL_Fact!$A:$A,G$3) | H21: =SUMIFS(qPL_Fact!$D:$D,qPL_Fact!$C:$C,$B21,qPL_Fact!$A:$A,H$3) | I21: =SUMIFS(qPL_Fact!$D:$D,qPL_Fact!$C:$C,$B21,qPL_Fact!$A:$A,I$3) | J21: =SUMIFS(qPL_Fact!$D:$D,qPL_Fact!$C:$C,$B21,qPL_Fact!$A:$A,J$3) | ... N21: =SUMIFS(qPL_Fact!$D:$D,qPL_Fact!$C:$C,$B21,qPL_Fact!$A:$A,N$3) | O21: =SUM(C21:N21)
A22: 4410 | B22: NSF Fees | C22: =SUMIFS(qPL_Fact!$D:$D,qPL_Fact!$C:$C,$B22,qPL_Fact!$A:$A,C$3) | D22: =SUMIFS(qPL_Fact!$D:$D,qPL_Fact!$C:$C,$B22,qPL_Fact!$A:$A,D$3) | E22: =SUMIFS(qPL_Fact!$D:$D,qPL_Fact!$C:$C,$B22,qPL_Fact!$A:$A,E$3) | F22: =SUMIFS(qPL_Fact!$D:$D,qPL_Fact!$C:$C,$B22,qPL_Fact!$A:$A,F$3) | G22: =SUMIFS(qPL_Fact!$D:$D,qPL_Fact!$C:$C,$B22,qPL_Fact!$A:$A,G$3) | H22: =SUMIFS(qPL_Fact!$D:$D,qPL_Fact!$C:$C,$B22,qPL_Fact!$A:$A,H$3) | I22: =SUMIFS(qPL_Fact!$D:$D,qPL_Fact!$C:$C,$B22,qPL_Fact!$A:$A,I$3) | J22: =SUMIFS(qPL_Fact!$D:$D,qPL_Fact!$C:$C,$B22,qPL_Fact!$A:$A,J$3) | ... N22: =SUMIFS(qPL_Fact!$D:$D,qPL_Fact!$C:$C,$B22,qPL_Fact!$A:$A,N$3) | O22: =SUM(C22:N22)
B23: Total Other Income | C23: =SUMIFS(qPL_Fact!$D:$D,qPL_Fact!$C:$C,$B23,qPL_Fact!$A:$A,C$3) | D23: =SUMIFS(qPL_Fact!$D:$D,qPL_Fact!$C:$C,$B23,qPL_Fact!$A:$A,D$3) | E23: =SUMIFS(qPL_Fact!$D:$D,qPL_Fact!$C:$C,$B23,qPL_Fact!$A:$A,E$3) | F23: =SUMIFS(qPL_Fact!$D:$D,qPL_Fact!$C:$C,$B23,qPL_Fact!$A:$A,F$3) | G23: =SUMIFS(qPL_Fact!$D:$D,qPL_Fact!$C:$C,$B23,qPL_Fact!$A:$A,G$3) | H23: =SUMIFS(qPL_Fact!$D:$D,qPL_Fact!$C:$C,$B23,qPL_Fact!$A:$A,H$3) | I23: =SUMIFS(qPL_Fact!$D:$D,qPL_Fact!$C:$C,$B23,qPL_Fact!$A:$A,I$3) | J23: =SUMIFS(qPL_Fact!$D:$D,qPL_Fact!$C:$C,$B23,qPL_Fact!$A:$A,J$3) | ... N23: =SUMIFS(qPL_Fact!$D:$D,qPL_Fact!$C:$C,$B23,qPL_Fact!$A:$A,N$3) | O23: =SUM(C23:N23)
B25: EFFECTIVE GROSS INCOME (EGI) | C25: =SUMIFS(qPL_Fact!$D:$D,qPL_Fact!$C:$C,$B25,qPL_Fact!$A:$A,C$3) | D25: =SUMIFS(qPL_Fact!$D:$D,qPL_Fact!$C:$C,$B25,qPL_Fact!$A:$A,D$3) | E25: =SUMIFS(qPL_Fact!$D:$D,qPL_Fact!$C:$C,$B25,qPL_Fact!$A:$A,E$3) | F25: =SUMIFS(qPL_Fact!$D:$D,qPL_Fact!$C:$C,$B25,qPL_Fact!$A:$A,F$3) | G25: =SUMIFS(qPL_Fact!$D:$D,qPL_Fact!$C:$C,$B25,qPL_Fact!$A:$A,G$3) | H25: =SUMIFS(qPL_Fact!$D:$D,qPL_Fact!$C:$C,$B25,qPL_Fact!$A:$A,H$3) | I25: =SUMIFS(qPL_Fact!$D:$D,qPL_Fact!$C:$C,$B25,qPL_Fact!$A:$A,I$3) | J25: =SUMIFS(qPL_Fact!$D:$D,qPL_Fact!$C:$C,$B25,qPL_Fact!$A:$A,J$3) | ... N25: =SUMIFS(qPL_Fact!$D:$D,qPL_Fact!$C:$C,$B25,qPL_Fact!$A:$A,N$3) | O25: =SUM(C25:N25)
B27: OPERATING EXPENSES | C27: =SUMIFS(qPL_Fact!$D:$D,qPL_Fact!$C:$C,$B27,qPL_Fact!$A:$A,C$3) | D27: =SUMIFS(qPL_Fact!$D:$D,qPL_Fact!$C:$C,$B27,qPL_Fact!$A:$A,D$3) | E27: =SUMIFS(qPL_Fact!$D:$D,qPL_Fact!$C:$C,$B27,qPL_Fact!$A:$A,E$3) | F27: =SUMIFS(qPL_Fact!$D:$D,qPL_Fact!$C:$C,$B27,qPL_Fact!$A:$A,F$3) | G27: =SUMIFS(qPL_Fact!$D:$D,qPL_Fact!$C:$C,$B27,qPL_Fact!$A:$A,G$3) | H27: =SUMIFS(qPL_Fact!$D:$D,qPL_Fact!$C:$C,$B27,qPL_Fact!$A:$A,H$3) | I27: =SUMIFS(qPL_Fact!$D:$D,qPL_Fact!$C:$C,$B27,qPL_Fact!$A:$A,I$3) | J27: =SUMIFS(qPL_Fact!$D:$D,qPL_Fact!$C:$C,$B27,qPL_Fact!$A:$A,J$3) | ... N27: =SUMIFS(qPL_Fact!$D:$D,qPL_Fact!$C:$C,$B27,qPL_Fact!$A:$A,N$3) | O27: =SUM(C27:N27)
A28: 6161 | B28: Real Estate Taxes | C28: =SUMIFS(qPL_Fact!$D:$D,qPL_Fact!$C:$C,$B28,qPL_Fact!$A:$A,C$3) | D28: =SUMIFS(qPL_Fact!$D:$D,qPL_Fact!$C:$C,$B28,qPL_Fact!$A:$A,D$3) | E28: =SUMIFS(qPL_Fact!$D:$D,qPL_Fact!$C:$C,$B28,qPL_Fact!$A:$A,E$3) | F28: =SUMIFS(qPL_Fact!$D:$D,qPL_Fact!$C:$C,$B28,qPL_Fact!$A:$A,F$3) | G28: =SUMIFS(qPL_Fact!$D:$D,qPL_Fact!$C:$C,$B28,qPL_Fact!$A:$A,G$3) | H28: =SUMIFS(qPL_Fact!$D:$D,qPL_Fact!$C:$C,$B28,qPL_Fact!$A:$A,H$3) | I28: =SUMIFS(qPL_Fact!$D:$D,qPL_Fact!$C:$C,$B28,qPL_Fact!$A:$A,I$3) | J28: =SUMIFS(qPL_Fact!$D:$D,qPL_Fact!$C:$C,$B28,qPL_Fact!$A:$A,J$3) | ... N28: =SUMIFS(qPL_Fact!$D:$D,qPL_Fact!$C:$C,$B28,qPL_Fact!$A:$A,N$3) | O28: =SUM(C28:N28)
A29: 6091 | B29: Property Insurance | C29: =SUMIFS(qPL_Fact!$D:$D,qPL_Fact!$C:$C,$B29,qPL_Fact!$A:$A,C$3) | D29: =SUMIFS(qPL_Fact!$D:$D,qPL_Fact!$C:$C,$B29,qPL_Fact!$A:$A,D$3) | E29: =SUMIFS(qPL_Fact!$D:$D,qPL_Fact!$C:$C,$B29,qPL_Fact!$A:$A,E$3) | F29: =SUMIFS(qPL_Fact!$D:$D,qPL_Fact!$C:$C,$B29,qPL_Fact!$A:$A,F$3) | G29: =SUMIFS(qPL_Fact!$D:$D,qPL_Fact!$C:$C,$B29,qPL_Fact!$A:$A,G$3) | H29: =SUMIFS(qPL_Fact!$D:$D,qPL_Fact!$C:$C,$B29,qPL_Fact!$A:$A,H$3) | I29: =SUMIFS(qPL_Fact!$D:$D,qPL_Fact!$C:$C,$B29,qPL_Fact!$A:$A,I$3) | J29: =SUMIFS(qPL_Fact!$D:$D,qPL_Fact!$C:$C,$B29,qPL_Fact!$A:$A,J$3) | ... N29: =SUMIFS(qPL_Fact!$D:$D,qPL_Fact!$C:$C,$B29,qPL_Fact!$A:$A,N$3) | O29: =SUM(C29:N29)
A30: 6002 | B30: Payroll | C30: =SUMIFS(qPL_Fact!$D:$D,qPL_Fact!$C:$C,$B30,qPL_Fact!$A:$A,C$3) | D30: =SUMIFS(qPL_Fact!$D:$D,qPL_Fact!$C:$C,$B30,qPL_Fact!$A:$A,D$3) | E30: =SUMIFS(qPL_Fact!$D:$D,qPL_Fact!$C:$C,$B30,qPL_Fact!$A:$A,E$3) | F30: =SUMIFS(qPL_Fact!$D:$D,qPL_Fact!$C:$C,$B30,qPL_Fact!$A:$A,F$3) | G30: =SUMIFS(qPL_Fact!$D:$D,qPL_Fact!$C:$C,$B30,qPL_Fact!$A:$A,G$3) | H30: =SUMIFS(qPL_Fact!$D:$D,qPL_Fact!$C:$C,$B30,qPL_Fact!$A:$A,H$3) | I30: =SUMIFS(qPL_Fact!$D:$D,qPL_Fact!$C:$C,$B30,qPL_Fact!$A:$A,I$3) | J30: =SUMIFS(qPL_Fact!$D:$D,qPL_Fact!$C:$C,$B30,qPL_Fact!$A:$A,J$3) | ... N30: =SUMIFS(qPL_Fact!$D:$D,qPL_Fact!$C:$C,$B30,qPL_Fact!$A:$A,N$3) | O30: =SUM(C30:N30)
A31: 6003 | B31: Advertising | C31: =SUMIFS(qPL_Fact!$D:$D,qPL_Fact!$C:$C,$B31,qPL_Fact!$A:$A,C$3) | D31: =SUMIFS(qPL_Fact!$D:$D,qPL_Fact!$C:$C,$B31,qPL_Fact!$A:$A,D$3) | E31: =SUMIFS(qPL_Fact!$D:$D,qPL_Fact!$C:$C,$B31,qPL_Fact!$A:$A,E$3) | F31: =SUMIFS(qPL_Fact!$D:$D,qPL_Fact!$C:$C,$B31,qPL_Fact!$A:$A,F$3) | G31: =SUMIFS(qPL_Fact!$D:$D,qPL_Fact!$C:$C,$B31,qPL_Fact!$A:$A,G$3) | H31: =SUMIFS(qPL_Fact!$D:$D,qPL_Fact!$C:$C,$B31,qPL_Fact!$A:$A,H$3) | I31: =SUMIFS(qPL_Fact!$D:$D,qPL_Fact!$C:$C,$B31,qPL_Fact!$A:$A,I$3) | J31: =SUMIFS(qPL_Fact!$D:$D,qPL_Fact!$C:$C,$B31,qPL_Fact!$A:$A,J$3) | ... N31: =SUMIFS(qPL_Fact!$D:$D,qPL_Fact!$C:$C,$B31,qPL_Fact!$A:$A,N$3) | O31: =SUM(C31:N31)
A32: 6171 | B32: Electricity | C32: =SUMIFS(qPL_Fact!$D:$D,qPL_Fact!$C:$C,$B32,qPL_Fact!$A:$A,C$3) | D32: =SUMIFS(qPL_Fact!$D:$D,qPL_Fact!$C:$C,$B32,qPL_Fact!$A:$A,D$3) | E32: =SUMIFS(qPL_Fact!$D:$D,qPL_Fact!$C:$C,$B32,qPL_Fact!$A:$A,E$3) | F32: =SUMIFS(qPL_Fact!$D:$D,qPL_Fact!$C:$C,$B32,qPL_Fact!$A:$A,F$3) | G32: =SUMIFS(qPL_Fact!$D:$D,qPL_Fact!$C:$C,$B32,qPL_Fact!$A:$A,G$3) | H32: =SUMIFS(qPL_Fact!$D:$D,qPL_Fact!$C:$C,$B32,qPL_Fact!$A:$A,H$3) | I32: =SUMIFS(qPL_Fact!$D:$D,qPL_Fact!$C:$C,$B32,qPL_Fact!$A:$A,I$3) | J32: =SUMIFS(qPL_Fact!$D:$D,qPL_Fact!$C:$C,$B32,qPL_Fact!$A:$A,J$3) | ... N32: =SUMIFS(qPL_Fact!$D:$D,qPL_Fact!$C:$C,$B32,qPL_Fact!$A:$A,N$3) | O32: =SUM(C32:N32)
A33: 6172 | B33: Gas | C33: =SUMIFS(qPL_Fact!$D:$D,qPL_Fact!$C:$C,$B33,qPL_Fact!$A:$A,C$3) | D33: =SUMIFS(qPL_Fact!$D:$D,qPL_Fact!$C:$C,$B33,qPL_Fact!$A:$A,D$3) | E33: =SUMIFS(qPL_Fact!$D:$D,qPL_Fact!$C:$C,$B33,qPL_Fact!$A:$A,E$3) | F33: =SUMIFS(qPL_Fact!$D:$D,qPL_Fact!$C:$C,$B33,qPL_Fact!$A:$A,F$3) | G33: =SUMIFS(qPL_Fact!$D:$D,qPL_Fact!$C:$C,$B33,qPL_Fact!$A:$A,G$3) | H33: =SUMIFS(qPL_Fact!$D:$D,qPL_Fact!$C:$C,$B33,qPL_Fact!$A:$A,H$3) | I33: =SUMIFS(qPL_Fact!$D:$D,qPL_Fact!$C:$C,$B33,qPL_Fact!$A:$A,I$3) | J33: =SUMIFS(qPL_Fact!$D:$D,qPL_Fact!$C:$C,$B33,qPL_Fact!$A:$A,J$3) | ... N33: =SUMIFS(qPL_Fact!$D:$D,qPL_Fact!$C:$C,$B33,qPL_Fact!$A:$A,N$3) | O33: =SUM(C33:N33)
A34: 6173 | B34: Water | C34: =SUMIFS(qPL_Fact!$D:$D,qPL_Fact!$C:$C,$B34,qPL_Fact!$A:$A,C$3) | D34: =SUMIFS(qPL_Fact!$D:$D,qPL_Fact!$C:$C,$B34,qPL_Fact!$A:$A,D$3) | E34: =SUMIFS(qPL_Fact!$D:$D,qPL_Fact!$C:$C,$B34,qPL_Fact!$A:$A,E$3) | F34: =SUMIFS(qPL_Fact!$D:$D,qPL_Fact!$C:$C,$B34,qPL_Fact!$A:$A,F$3) | G34: =SUMIFS(qPL_Fact!$D:$D,qPL_Fact!$C:$C,$B34,qPL_Fact!$A:$A,G$3) | H34: =SUMIFS(qPL_Fact!$D:$D,qPL_Fact!$C:$C,$B34,qPL_Fact!$A:$A,H$3) | I34: =SUMIFS(qPL_Fact!$D:$D,qPL_Fact!$C:$C,$B34,qPL_Fact!$A:$A,I$3) | J34: =SUMIFS(qPL_Fact!$D:$D,qPL_Fact!$C:$C,$B34,qPL_Fact!$A:$A,J$3) | ... N34: =SUMIFS(qPL_Fact!$D:$D,qPL_Fact!$C:$C,$B34,qPL_Fact!$A:$A,N$3) | O34: =SUM(C34:N34)
A35: 6175 | B35: Garbage & Recycling | C35: =SUMIFS(qPL_Fact!$D:$D,qPL_Fact!$C:$C,$B35,qPL_Fact!$A:$A,C$3) | D35: =SUMIFS(qPL_Fact!$D:$D,qPL_Fact!$C:$C,$B35,qPL_Fact!$A:$A,D$3) | E35: =SUMIFS(qPL_Fact!$D:$D,qPL_Fact!$C:$C,$B35,qPL_Fact!$A:$A,E$3) | F35: =SUMIFS(qPL_Fact!$D:$D,qPL_Fact!$C:$C,$B35,qPL_Fact!$A:$A,F$3) | G35: =SUMIFS(qPL_Fact!$D:$D,qPL_Fact!$C:$C,$B35,qPL_Fact!$A:$A,G$3) | H35: =SUMIFS(qPL_Fact!$D:$D,qPL_Fact!$C:$C,$B35,qPL_Fact!$A:$A,H$3) | I35: =SUMIFS(qPL_Fact!$D:$D,qPL_Fact!$C:$C,$B35,qPL_Fact!$A:$A,I$3) | J35: =SUMIFS(qPL_Fact!$D:$D,qPL_Fact!$C:$C,$B35,qPL_Fact!$A:$A,J$3) | ... N35: =SUMIFS(qPL_Fact!$D:$D,qPL_Fact!$C:$C,$B35,qPL_Fact!$A:$A,N$3) | O35: =SUM(C35:N35)
A36: 6176 | B36: Internet | C36: =SUMIFS(qPL_Fact!$D:$D,qPL_Fact!$C:$C,$B36,qPL_Fact!$A:$A,C$3) | D36: =SUMIFS(qPL_Fact!$D:$D,qPL_Fact!$C:$C,$B36,qPL_Fact!$A:$A,D$3) | E36: =SUMIFS(qPL_Fact!$D:$D,qPL_Fact!$C:$C,$B36,qPL_Fact!$A:$A,E$3) | F36: =SUMIFS(qPL_Fact!$D:$D,qPL_Fact!$C:$C,$B36,qPL_Fact!$A:$A,F$3) | G36: =SUMIFS(qPL_Fact!$D:$D,qPL_Fact!$C:$C,$B36,qPL_Fact!$A:$A,G$3) | H36: =SUMIFS(qPL_Fact!$D:$D,qPL_Fact!$C:$C,$B36,qPL_Fact!$A:$A,H$3) | I36: =SUMIFS(qPL_Fact!$D:$D,qPL_Fact!$C:$C,$B36,qPL_Fact!$A:$A,I$3) | J36: =SUMIFS(qPL_Fact!$D:$D,qPL_Fact!$C:$C,$B36,qPL_Fact!$A:$A,J$3) | ... N36: =SUMIFS(qPL_Fact!$D:$D,qPL_Fact!$C:$C,$B36,qPL_Fact!$A:$A,N$3) | O36: =SUM(C36:N36)
A37: 6111 | B37: Management Fee (4%) | C37: =SUMIFS(qPL_Fact!$D:$D,qPL_Fact!$C:$C,$B37,qPL_Fact!$A:$A,C$3) | D37: =SUMIFS(qPL_Fact!$D:$D,qPL_Fact!$C:$C,$B37,qPL_Fact!$A:$A,D$3) | E37: =SUMIFS(qPL_Fact!$D:$D,qPL_Fact!$C:$C,$B37,qPL_Fact!$A:$A,E$3) | F37: =SUMIFS(qPL_Fact!$D:$D,qPL_Fact!$C:$C,$B37,qPL_Fact!$A:$A,F$3) | G37: =SUMIFS(qPL_Fact!$D:$D,qPL_Fact!$C:$C,$B37,qPL_Fact!$A:$A,G$3) | H37: =SUMIFS(qPL_Fact!$D:$D,qPL_Fact!$C:$C,$B37,qPL_Fact!$A:$A,H$3) | I37: =SUMIFS(qPL_Fact!$D:$D,qPL_Fact!$C:$C,$B37,qPL_Fact!$A:$A,I$3) | J37: =SUMIFS(qPL_Fact!$D:$D,qPL_Fact!$C:$C,$B37,qPL_Fact!$A:$A,J$3) | ... N37: =SUMIFS(qPL_Fact!$D:$D,qPL_Fact!$C:$C,$B37,qPL_Fact!$A:$A,N$3) | O37: =SUM(C37:N37)
A38: 6073 | B38: General Maint. Labor | C38: =SUMIFS(qPL_Fact!$D:$D,qPL_Fact!$C:$C,$B38,qPL_Fact!$A:$A,C$3) | D38: =SUMIFS(qPL_Fact!$D:$D,qPL_Fact!$C:$C,$B38,qPL_Fact!$A:$A,D$3) | E38: =SUMIFS(qPL_Fact!$D:$D,qPL_Fact!$C:$C,$B38,qPL_Fact!$A:$A,E$3) | F38: =SUMIFS(qPL_Fact!$D:$D,qPL_Fact!$C:$C,$B38,qPL_Fact!$A:$A,F$3) | G38: =SUMIFS(qPL_Fact!$D:$D,qPL_Fact!$C:$C,$B38,qPL_Fact!$A:$A,G$3) | H38: =SUMIFS(qPL_Fact!$D:$D,qPL_Fact!$C:$C,$B38,qPL_Fact!$A:$A,H$3) | I38: =SUMIFS(qPL_Fact!$D:$D,qPL_Fact!$C:$C,$B38,qPL_Fact!$A:$A,I$3) | J38: =SUMIFS(qPL_Fact!$D:$D,qPL_Fact!$C:$C,$B38,qPL_Fact!$A:$A,J$3) | ... N38: =SUMIFS(qPL_Fact!$D:$D,qPL_Fact!$C:$C,$B38,qPL_Fact!$A:$A,N$3) | O38: =SUM(C38:N38)
A39: 6074 | B39: Landscaping | C39: =SUMIFS(qPL_Fact!$D:$D,qPL_Fact!$C:$C,$B39,qPL_Fact!$A:$A,C$3) | D39: =SUMIFS(qPL_Fact!$D:$D,qPL_Fact!$C:$C,$B39,qPL_Fact!$A:$A,D$3) | E39: =SUMIFS(qPL_Fact!$D:$D,qPL_Fact!$C:$C,$B39,qPL_Fact!$A:$A,E$3) | F39: =SUMIFS(qPL_Fact!$D:$D,qPL_Fact!$C:$C,$B39,qPL_Fact!$A:$A,F$3) | G39: =SUMIFS(qPL_Fact!$D:$D,qPL_Fact!$C:$C,$B39,qPL_Fact!$A:$A,G$3) | H39: =SUMIFS(qPL_Fact!$D:$D,qPL_Fact!$C:$C,$B39,qPL_Fact!$A:$A,H$3) | I39: =SUMIFS(qPL_Fact!$D:$D,qPL_Fact!$C:$C,$B39,qPL_Fact!$A:$A,I$3) | J39: =SUMIFS(qPL_Fact!$D:$D,qPL_Fact!$C:$C,$B39,qPL_Fact!$A:$A,J$3) | ... N39: =SUMIFS(qPL_Fact!$D:$D,qPL_Fact!$C:$C,$B39,qPL_Fact!$A:$A,N$3) | O39: =SUM(C39:N39)
... A59: 6179 | B59: Asset Mgmt Fee | C59: =SUMIFS(qPL_Fact!$D:$D,qPL_Fact!$C:$C,$B59,qPL_Fact!$A:$A,C$3) | D59: =SUMIFS(qPL_Fact!$D:$D,qPL_Fact!$C:$C,$B59,qPL_Fact!$A:$A,D$3) | E59: =SUMIFS(qPL_Fact!$D:$D,qPL_Fact!$C:$C,$B59,qPL_Fact!$A:$A,E$3) | F59: =SUMIFS(qPL_Fact!$D:$D,qPL_Fact!$C:$C,$B59,qPL_Fact!$A:$A,F$3) | G59: =SUMIFS(qPL_Fact!$D:$D,qPL_Fact!$C:$C,$B59,qPL_Fact!$A:$A,G$3) | H59: =SUMIFS(qPL_Fact!$D:$D,qPL_Fact!$C:$C,$B59,qPL_Fact!$A:$A,H$3) | I59: =SUMIFS(qPL_Fact!$D:$D,qPL_Fact!$C:$C,$B59,qPL_Fact!$A:$A,I$3) | J59: =SUMIFS(qPL_Fact!$D:$D,qPL_Fact!$C:$C,$B59,qPL_Fact!$A:$A,J$3) | ... N59: =SUMIFS(qPL_Fact!$D:$D,qPL_Fact!$C:$C,$B59,qPL_Fact!$A:$A,N$3) | O59: =SUM(C59:N59)
B60: Total Operating Expenses | C60: =SUMIFS(qPL_Fact!$D:$D,qPL_Fact!$C:$C,$B60,qPL_Fact!$A:$A,C$3) | D60: =SUMIFS(qPL_Fact!$D:$D,qPL_Fact!$C:$C,$B60,qPL_Fact!$A:$A,D$3) | E60: =SUMIFS(qPL_Fact!$D:$D,qPL_Fact!$C:$C,$B60,qPL_Fact!$A:$A,E$3) | F60: =SUMIFS(qPL_Fact!$D:$D,qPL_Fact!$C:$C,$B60,qPL_Fact!$A:$A,F$3) | G60: =SUMIFS(qPL_Fact!$D:$D,qPL_Fact!$C:$C,$B60,qPL_Fact!$A:$A,G$3) | H60: =SUMIFS(qPL_Fact!$D:$D,qPL_Fact!$C:$C,$B60,qPL_Fact!$A:$A,H$3) | I60: =SUMIFS(qPL_Fact!$D:$D,qPL_Fact!$C:$C,$B60,qPL_Fact!$A:$A,I$3) | J60: =SUMIFS(qPL_Fact!$D:$D,qPL_Fact!$C:$C,$B60,qPL_Fact!$A:$A,J$3) | ... N60: =SUMIFS(qPL_Fact!$D:$D,qPL_Fact!$C:$C,$B60,qPL_Fact!$A:$A,N$3) | O60: =SUM(C60:N60)
B62: NET OPERATING INCOME (NOI) | C62: =SUMIFS(qPL_Fact!$D:$D,qPL_Fact!$C:$C,$B62,qPL_Fact!$A:$A,C$3) | D62: =SUMIFS(qPL_Fact!$D:$D,qPL_Fact!$C:$C,$B62,qPL_Fact!$A:$A,D$3) | E62: =SUMIFS(qPL_Fact!$D:$D,qPL_Fact!$C:$C,$B62,qPL_Fact!$A:$A,E$3) | F62: =SUMIFS(qPL_Fact!$D:$D,qPL_Fact!$C:$C,$B62,qPL_Fact!$A:$A,F$3) | G62: =SUMIFS(qPL_Fact!$D:$D,qPL_Fact!$C:$C,$B62,qPL_Fact!$A:$A,G$3) | H62: =SUMIFS(qPL_Fact!$D:$D,qPL_Fact!$C:$C,$B62,qPL_Fact!$A:$A,H$3) | I62: =SUMIFS(qPL_Fact!$D:$D,qPL_Fact!$C:$C,$B62,qPL_Fact!$A:$A,I$3) | J62: =SUMIFS(qPL_Fact!$D:$D,qPL_Fact!$C:$C,$B62,qPL_Fact!$A:$A,J$3) | ... N62: =SUMIFS(qPL_Fact!$D:$D,qPL_Fact!$C:$C,$B62,qPL_Fact!$A:$A,N$3) | O62: =SUM(C62:N62)
B64: DEBT SERVICE | C64: =SUMIFS(qPL_Fact!$D:$D,qPL_Fact!$C:$C,$B64,qPL_Fact!$A:$A,C$3) | D64: =SUMIFS(qPL_Fact!$D:$D,qPL_Fact!$C:$C,$B64,qPL_Fact!$A:$A,D$3) | E64: =SUMIFS(qPL_Fact!$D:$D,qPL_Fact!$C:$C,$B64,qPL_Fact!$A:$A,E$3) | F64: =SUMIFS(qPL_Fact!$D:$D,qPL_Fact!$C:$C,$B64,qPL_Fact!$A:$A,F$3) | G64: =SUMIFS(qPL_Fact!$D:$D,qPL_Fact!$C:$C,$B64,qPL_Fact!$A:$A,G$3) | H64: =SUMIFS(qPL_Fact!$D:$D,qPL_Fact!$C:$C,$B64,qPL_Fact!$A:$A,H$3) | I64: =SUMIFS(qPL_Fact!$D:$D,qPL_Fact!$C:$C,$B64,qPL_Fact!$A:$A,I$3) | J64: =SUMIFS(qPL_Fact!$D:$D,qPL_Fact!$C:$C,$B64,qPL_Fact!$A:$A,J$3) | ... N64: =SUMIFS(qPL_Fact!$D:$D,qPL_Fact!$C:$C,$B64,qPL_Fact!$A:$A,N$3) | O64: =SUM(C64:N64)
...

Sheet Trailing Analysis
A1: The Groves Apartments | Trailing Analysis
A2: Period-over-period variance | Current month: Dec-25
A3: GL | B3: Account | C3: Dec-25 | D3: Nov-25 | E3: Δ MoM | F3: Oct-25–Dec-25 | G3: Jul-25–Sep-25 | H3: Δ T3 | I3: Jan-25–Dec-25 | J3: Aug-24–Jul-25 | K3: Δ T12
